Workbook

Sheet Summary
A1: Gunvatta Yatra UP – 4-Team Rollout Summary
A2: All figures pull from 'Route Plan' – edit dates/teams there and this sheet updates. Yellow = to fill.
A4: Team | B4: Zone | C4: Team member (1 person) | D4: Home base | E4: Yatras | F4: Districts covered | G4: First solo Yatra | H4: Last Yatra | I4: Joint Yatras attended | J4: Reserve slots
A5: Team 1 – West | B5: Bareilly · Moradabad · Saharanpur · Meerut (NCR) | E5: =COUNTIFS('Route Plan'!$C$5:$C$77,A5,'Route Plan'!$I$5:$I$77,">0") -> 16 | F5: =SUMIF('Route Plan'!$C$5:$C$77,A5,'Route Plan'!$I$5:$I$77) -> 17 | G5: =_xlfn.MINIFS('Route Plan'!$J$5:$J$77,'Route Plan'!$C$5:$C$77,A5,'Route Plan'!$I$5:$I$77,">0") -> 46325 | H5: =_xlfn.MAXIFS('Route Plan'!$J$5:$J$77,'Route Plan'!$C$5:$C$77,A5,'Route Plan'!$I$5:$I$77,">0") -> 46465 | I5: =COUNTIF('Route Plan'!$C$5:$C$77,"Joint (All 4)") -> 1 | J5: =COUNTIFS('Route Plan'!$C$5:$C$77,A5,'Route Plan'!$I$5:$I$77,0) -> 2
A6: Team 2 – East | B6: Gorakhpur · Basti · Devipatan · Azamgarh · Varanasi | C6: Pankaj (confirm) | E6: =COUNTIFS('Route Plan'!$C$5:$C$77,A6,'Route Plan'!$I$5:$I$77,">0") -> 16 | F6: =SUMIF('Route Plan'!$C$5:$C$77,A6,'Route Plan'!$I$5:$I$77) -> 17 | G6: =_xlfn.MINIFS('Route Plan'!$J$5:$J$77,'Route Plan'!$C$5:$C$77,A6,'Route Plan'!$I$5:$I$77,">0") -> 46325 | H6: =_xlfn.MAXIFS('Route Plan'!$J$5:$J$77,'Route Plan'!$C$5:$C$77,A6,'Route Plan'!$I$5:$I$77,">0") -> 46465 | I6: =COUNTIF('Route Plan'!$C$5:$C$77,"Joint (All 4)") -> 1 | J6: =COUNTIFS('Route Plan'!$C$5:$C$77,A6,'Route Plan'!$I$5:$I$77,0) -> 2
A7: Team 3 – Central | B7: Lucknow belt · Ayodhya · Jaunpur–Vindhyachal · Prayagraj | E7: =COUNTIFS('Route Plan'!$C$5:$C$77,A7,'Route Plan'!$I$5:$I$77,">0") -> 15 | F7: =SUMIF('Route Plan'!$C$5:$C$77,A7,'Route Plan'!$I$5:$I$77) -> 17 | G7: =_xlfn.MINIFS('Route Plan'!$J$5:$J$77,'Route Plan'!$C$5:$C$77,A7,'Route Plan'!$I$5:$I$77,">0") -> 46325 | H7: =_xlfn.MAXIFS('Route Plan'!$J$5:$J$77,'Route Plan'!$C$5:$C$77,A7,'Route Plan'!$I$5:$I$77,">0") -> 46458 | I7: =COUNTIF('Route Plan'!$C$5:$C$77,"Joint (All 4)") -> 1 | J7: =COUNTIFS('Route Plan'!$C$5:$C$77,A7,'Route Plan'!$I$5:$I$77,0) -> 3
A8: Team 4 – South-West & Bundelkhand | B8: Kanpur · Agra · Aligarh · Jhansi · Chitrakoot | E8: =COUNTIFS('Route Plan'!$C$5:$C$77,A8,'Route Plan'!$I$5:$I$77,">0") -> 15 | F8: =SUMIF('Route Plan'!$C$5:$C$77,A8,'Route Plan'!$I$5:$I$77) -> 23 | G8: =_xlfn.MINIFS('Route Plan'!$J$5:$J$77,'Route Plan'!$C$5:$C$77,A8,'Route Plan'!$I$5:$I$77,">0") -> 46325 | H8: =_xlfn.MAXIFS('Route Plan'!$J$5:$J$77,'Route Plan'!$C$5:$C$77,A8,'Route Plan'!$I$5:$I$77,">0") -> 46465 | I8: =COUNTIF('Route Plan'!$C$5:$C$77,"Joint (All 4)") -> 1 | J8: =COUNTIFS('Route Plan'!$C$5:$C$77,A8,'Route Plan'!$I$5:$I$77,0) -> 3
A9: Joint (All 4) | B9: State launch – all 4 members together | C9: All 4 members | E9: =COUNTIFS('Route Plan'!$C$5:$C$77,A9,'Route Plan'!$I$5:$I$77,">0") -> 1 | F9: =SUMIF('Route Plan'!$C$5:$C$77,A9,'Route Plan'!$I$5:$I$77) -> 1 | G9: =_xlfn.MINIFS('Route Plan'!$J$5:$J$77,'Route Plan'!$C$5:$C$77,A9) -> 46318 | H9: =_xlfn.MAXIFS('Route Plan'!$J$5:$J$77,'Route Plan'!$C$5:$C$77,A9) -> 46318 | I9: — | J9: —
A10: TOTAL | E10: =SUM(E5:E9) -> 63 | F10: =SUM(F5:F9) -> 75 | G10: =MIN(G5:G9) -> 46318 | H10: =MAX(H5:H9) -> 46465 | J10: =SUM(J5:J8) -> 10
A11: Check: districts covered should equal 75 → | F11: =IF(F10=75,"✔ All 75 districts","✖ Check coverage") -> ✔ All 75 districts
A13: Yatras per month
A14: Team | B14: 46296 | C14: 46327 | D14: 46357 | E14: 46388 | F14: 46419 | G14: 46447 | H14: Total
A15: Joint (All 4) | B15: =COUNTIFS('Route Plan'!$C$5:$C$77,$A15,'Route Plan'!$I$5:$I$77,">0",'Route Plan'!$J$5:$J$77,">="&B$14,'Route Plan'!$J$5:$J$77,"<"&EDATE(B$14,1)) -> 1 | C15: =COUNTIFS('Route Plan'!$C$5:$C$77,$A15,'Route Plan'!$I$5:$I$77,">0",'Route Plan'!$J$5:$J$77,">="&C$14,'Route Plan'!$J$5:$J$77,"<"&EDATE(C$14,1)) -> 0 | D15: =COUNTIFS('Route Plan'!$C$5:$C$77,$A15,'Route Plan'!$I$5:$I$77,">0",'Route Plan'!$J$5:$J$77,">="&D$14,'Route Plan'!$J$5:$J$77,"<"&EDATE(D$14,1)) -> 0 | E15: =COUNTIFS('Route Plan'!$C$5:$C$77,$A15,'Route Plan'!$I$5:$I$77,">0",'Route Plan'!$J$5:$J$77,">="&E$14,'Route Plan'!$J$5:$J$77,"<"&EDATE(E$14,1)) -> 0 | F15: =COUNTIFS('Route Plan'!$C$5:$C$77,$A15,'Route Plan'!$I$5:$I$77,">0",'Route Plan'!$J$5:$J$77,">="&F$14,'Route Plan'!$J$5:$J$77,"<"&EDATE(F$14,1)) -> 0 | G15: =COUNTIFS('Route Plan'!$C$5:$C$77,$A15,'Route Plan'!$I$5:$I$77,">0",'Route Plan'!$J$5:$J$77,">="&G$14,'Route Plan'!$J$5:$J$77,"<"&EDATE(G$14,1)) -> 0 | H15: =SUM(B15:G15) -> 1
A16: Team 1 – West | B16: =COUNTIFS('Route Plan'!$C$5:$C$77,$A16,'Route Plan'!$I$5:$I$77,">0",'Route Plan'!$J$5:$J$77,">="&B$14,'Route Plan'!$J$5:$J$77,"<"&EDATE(B$14,1)) -> 1 | C16: =COUNTIFS('Route Plan'!$C$5:$C$77,$A16,'Route Plan'!$I$5:$I$77,">0",'Route Plan'!$J$5:$J$77,">="&C$14,'Route Plan'!$J$5:$J$77,"<"&EDATE(C$14,1)) -> 2 | D16: =COUNTIFS('Route Plan'!$C$5:$C$77,$A16,'Route Plan'!$I$5:$I$77,">0",'Route Plan'!$J$5:$J$77,">="&D$14,'Route Plan'!$J$5:$J$77,"<"&EDATE(D$14,1)) -> 2 | E16: =COUNTIFS('Route Plan'!$C$5:$C$77,$A16,'Route Plan'!$I$5:$I$77,">0",'Route Plan'!$J$5:$J$77,">="&E$14,'Route Plan'!$J$5:$J$77,"<"&EDATE(E$14,1)) -> 4 | F16: =COUNTIFS('Route Plan'!$C$5:$C$77,$A16,'Route Plan'!$I$5:$I$77,">0",'Route Plan'!$J$5:$J$77,">="&F$14,'Route Plan'!$J$5:$J$77,"<"&EDATE(F$14,1)) -> 4 | G16: =COUNTIFS('Route Plan'!$C$5:$C$77,$A16,'Route Plan'!$I$5:$I$77,">0",'Route Plan'!$J$5:$J$77,">="&G$14,'Route Plan'!$J$5:$J$77,"<"&EDATE(G$14,1)) -> 3 | H16: =SUM(B16:G16) -> 16
A17: Team 2 – East | B17: =COUNTIFS('Route Plan'!$C$5:$C$77,$A17,'Route Plan'!$I$5:$I$77,">0",'Route Plan'!$J$5:$J$77,">="&B$14,'Route Plan'!$J$5:$J$77,"<"&EDATE(B$14,1)) -> 1 | C17: =COUNTIFS('Route Plan'!$C$5:$C$77,$A17,'Route Plan'!$I$5:$I$77,">0",'Route Plan'!$J$5:$J$77,">="&C$14,'Route Plan'!$J$5:$J$77,"<"&EDATE(C$14,1)) -> 2 | D17: =COUNTIFS('Route Plan'!$C$5:$C$77,$A17,'Route Plan'!$I$5:$I$77,">0",'Route Plan'!$J$5:$J$77,">="&D$14,'Route Plan'!$J$5:$J$77,"<"&EDATE(D$14,1)) -> 2 | E17: =COUNTIFS('Route Plan'!$C$5:$C$77,$A17,'Route Plan'!$I$5:$I$77,">0",'Route Plan'!$J$5:$J$77,">="&E$14,'Route Plan'!$J$5:$J$77,"<"&EDATE(E$14,1)) -> 4 | F17: =COUNTIFS('Route Plan'!$C$5:$C$77,$A17,'Route Plan'!$I$5:$I$77,">0",'Route Plan'!$J$5:$J$77,">="&F$14,'Route Plan'!$J$5:$J$77,"<"&EDATE(F$14,1)) -> 4 | G17: =COUNTIFS('Route Plan'!$C$5:$C$77,$A17,'Route Plan'!$I$5:$I$77,">0",'Route Plan'!$J$5:$J$77,">="&G$14,'Route Plan'!$J$5:$J$77,"<"&EDATE(G$14,1)) -> 3 | H17: =SUM(B17:G17) -> 16
A18: Team 3 – Central | B18: =COUNTIFS('Route Plan'!$C$5:$C$77,$A18,'Route Plan'!$I$5:$I$77,">0",'Route Plan'!$J$5:$J$77,">="&B$14,'Route Plan'!$J$5:$J$77,"<"&EDATE(B$14,1)) -> 1 | C18: =COUNTIFS('Route Plan'!$C$5:$C$77,$A18,'Route Plan'!$I$5:$I$77,">0",'Route Plan'!$J$5:$J$77,">="&C$14,'Route Plan'!$J$5:$J$77,"<"&EDATE(C$14,1)) -> 2 | D18: =COUNTIFS('Route Plan'!$C$5:$C$77,$A18,'Route Plan'!$I$5:$I$77,">0",'Route Plan'!$J$5:$J$77,">="&D$14,'Route Plan'!$J$5:$J$77,"<"&EDATE(D$14,1)) -> 2 | E18: =COUNTIFS('Route Plan'!$C$5:$C$77,$A18,'Route Plan'!$I$5:$I$77,">0",'Route Plan'!$J$5:$J$77,">="&E$14,'Route Plan'!$J$5:$J$77,"<"&EDATE(E$14,1)) -> 4 | F18: =COUNTIFS('Route Plan'!$C$5:$C$77,$A18,'Route Plan'!$I$5:$I$77,">0",'Route Plan'!$J$5:$J$77,">="&F$14,'Route Plan'!$J$5:$J$77,"<"&EDATE(F$14,1)) -> 4 | G18: =COUNTIFS('Route Plan'!$C$5:$C$77,$A18,'Route Plan'!$I$5:$I$77,">0",'Route Plan'!$J$5:$J$77,">="&G$14,'Route Plan'!$J$5:$J$77,"<"&EDATE(G$14,1)) -> 2 | H18: =SUM(B18:G18) -> 15
A19: Team 4 – South-West & Bundelkhand | B19: =COUNTIFS('Route Plan'!$C$5:$C$77,$A19,'Route Plan'!$I$5:$I$77,">0",'Route Plan'!$J$5:$J$77,">="&B$14,'Route Plan'!$J$5:$J$77,"<"&EDATE(B$14,1)) -> 1 | C19: =COUNTIFS('Route Plan'!$C$5:$C$77,$A19,'Route Plan'!$I$5:$I$77,">0",'Route Plan'!$J$5:$J$77,">="&C$14,'Route Plan'!$J$5:$J$77,"<"&EDATE(C$14,1)) -> 2 | D19: =COUNTIFS('Route Plan'!$C$5:$C$77,$A19,'Route Plan'!$I$5:$I$77,">0",'Route Plan'!$J$5:$J$77,">="&D$14,'Route Plan'!$J$5:$J$77,"<"&EDATE(D$14,1)) -> 2 | E19: =COUNTIFS('Route Plan'!$C$5:$C$77,$A19,'Route Plan'!$I$5:$I$77,">0",'Route Plan'!$J$5:$J$77,">="&E$14,'Route Plan'!$J$5:$J$77,"<"&EDATE(E$14,1)) -> 4 | F19: =COUNTIFS('Route Plan'!$C$5:$C$77,$A19,'Route Plan'!$I$5:$I$77,">0",'Route Plan'!$J$5:$J$77,">="&F$14,'Route Plan'!$J$5:$J$77,"<"&EDATE(F$14,1)) -> 3 | G19: =COUNTIFS('Route Plan'!$C$5:$C$77,$A19,'Route Plan'!$I$5:$I$77,">0",'Route Plan'!$J$5:$J$77,">="&G$14,'Route Plan'!$J$5:$J$77,"<"&EDATE(G$14,1)) -> 3 | H19: =SUM(B19:G19) -> 15
A20: TOTAL | B20: =SUM(B15:B19) -> 5 | C20: =SUM(C15:C19) -> 8 | D20: =SUM(D15:D19) -> 8 | E20: =SUM(E15:E19) -> 16 | F20: =SUM(F15:F19) -> 15 | G20: =SUM(G15:G19) -> 11 | H20: =SUM(H15:H19) -> 63
A22: How the plan works
A23: 1. Only the LUCKNOW launch (Fri 23 Oct) is joint – all 4 members together. From Sat 24 Oct each member works independently in his own zone.
A24: 2. First solo Yatra on Fri 30 Oct: Bareilly (T1), Gorakhpur (T2), Barabanki (T3), Kanpur Nagar (T4) – all within a day's drive of Lucknow.
A25: 3. 6 Nov (Dhanteras/Diwali) and 13 Nov (Bhai Dooj on Wed 11 Nov) are skipped – use these 2 weeks for CMO letters & hospital lists for Circuit 1 and 2.
A26: 4. Every Yatra is on FRIDAY; the team member reaches the district Monday/Tuesday (3–4 days for CMO meeting, SPOC, mobilisation).
A27: 5. One circuit = 4 neighbouring districts on 4 consecutive Fridays: Circuit 1 (20 Nov–11 Dec), Circuit 2 (Jan), Circuit 3 (Feb), Circuit 4 (Mar) → 4 teams × 4 = 16 Yatras a month.
A28: 6. Holiday rule (Friday Calendar sheet): Wed/Thu holiday → week skipped; Friday holiday → Saturday (26 Mar Good Friday → Sat 27 Mar, kept as reserve).
A29: 7. All 75 districts finish by 19 Mar 2027. 18 Dec and 27 Mar (plus 26 Feb for T4 and 19 Mar for T3) are RESERVE slots for any postponed Yatra – no April spill-over needed.
A30: 8. Up to 4 parallel Yatras every Friday → 4 distinct NABH faculty needed per Friday (Friday Calendar col P).

Sheet UP Holidays
A1: UP Holidays & Festivals – Oct 2026 to Apr 2027
A2: Blocks Yatra? = Yes → counts as holiday in the Friday rule · Caution → Yatra allowed but flagged · Edit column E to change the rule. 2027 UP list not yet notified – 2027 dates indicative; Islamic dates moon-dependent.
A4: Date | B4: Day | C4: Holiday / Festival | D4: Type | E4: Blocks Yatra? | F4: Note
A5: 46297 | B5: =TEXT(A5,"dddd") -> Friday | C5: Mahatma Gandhi Jayanti | D5: Gazetted | E5: Yes | F5: Before launch
A6: 46314 | B6: =TEXT(A6,"dddd") -> Monday | C6: Maha Navami | D6: Gazetted | E6: Yes | F6: Lucknow launch prep week
A7: 46315 | B7: =TEXT(A7,"dddd") -> Tuesday | C7: Dussehra / Vijayadashami | D7: Gazetted | E7: Yes | F7: Some lists show 21 Oct (Wed) – if UP notifies 21 Oct, 23 Oct launch falls in a mobilisation-risk week
A8: 46321 | B8: =TEXT(A8,"dddd") -> Monday | C8: Maharishi Valmiki Jayanti | D8: Gazetted | E8: Yes | F8: Monday – no clash
A9: 46324 | B9: =TEXT(A9,"dddd") -> Thursday | C9: Karva Chauth | D9: Restricted | E9: Caution | F9: Thursday before Gorakhpur (30 Oct)
A10: 46326 | B10: =TEXT(A10,"dddd") -> Saturday | C10: Sardar Patel / Acharya Narendra Dev Jayanti | D10: Gazetted | E10: Yes | F10: Saturday
A11: 46332 | B11: =TEXT(A11,"dddd") -> Friday | C11: Dhanteras (Diwali week) | D11: Major festival (not gazetted) | E11: Yes | F11: Practical block – hospital owners & CMO staff busy
A12: 46333 | B12: =TEXT(A12,"dddd") -> Saturday | C12: Choti Diwali / Narak Chaturdashi | D12: Observance | E12: Yes | F12: Blocks Saturday shift for 6 Nov
A13: 46334 | B13: =TEXT(A13,"dddd") -> Sunday | C13: Deepawali | D13: Gazetted | E13: Yes | F13: Sunday
A14: 46335 | B14: =TEXT(A14,"dddd") -> Monday | C14: Govardhan Puja | D14: Gazetted | E14: Yes | F14: Some lists show 10 Nov
A15: 46337 | B15: =TEXT(A15,"dddd") -> Wednesday | C15: Bhai Dooj / Chitragupta Jayanti | D15: Gazetted | E15: Yes | F15: Wednesday → 13 Nov skipped
A16: 46341 | B16: =TEXT(A16,"dddd") -> Sunday | C16: Chhath Puja (evening arghya) | D16: Restricted | E16: Caution | F16: Heavy in East UP – Kushi Nagar moved to 27 Nov
... A19: 46379 | B19: =TEXT(A19,"dddd") -> Wednesday | C19: Chaudhary Charan Singh Jayanti / Hazrat Ali Jayanti | D19: Gazetted | E19: Yes | F19: Wednesday → 25 Dec week skipped
A20: 46380 | B20: =TEXT(A20,"dddd") -> Thursday | C20: Christmas Eve | D20: Restricted | E20: Caution
A21: 46381 | B21: =TEXT(A21,"dddd") -> Friday | C21: Christmas | D21: Gazetted | E21: Yes | F21: Friday
A22: 46388 | B22: =TEXT(A22,"dddd") -> Friday | C22: New Year's Day | D22: Restricted | E22: Caution | F22: Year-end break applied via override
A23: 46401 | B23: =TEXT(A23,"dddd") -> Thursday | C23: Makar Sankranti / Khichdi | D23: Restricted | E23: Caution | F23: Gorakhpur Khichdi mela, Prayagraj Magh Mela, Ayodhya snan – no team in these on 15 Jan
A24: 46413 | B24: =TEXT(A24,"dddd") -> Tuesday | C24: Republic Day | D24: National | E24: Yes | F24: Tuesday – no clash
A25: 46429 | B25: =TEXT(A25,"dddd") -> Thursday | C25: Basant Panchami (approx.) | D25: Restricted | E25: Caution | F25: Magh Mela snan day – Prayagraj avoided in Feb
A26: 46438 | B26: =TEXT(A26,"dddd") -> Saturday | C26: Sant Ravidas Jayanti / Magh Purnima (approx.) | D26: Gazetted | E26: Yes | F26: Saturday
A27: 46452 | B27: =TEXT(A27,"dddd") -> Saturday | C27: Maha Shivratri (approx.) | D27: Gazetted | E27: Yes | F27: Saturday
A28: 46455 | B28: =TEXT(A28,"dddd") -> Tuesday | C28: Eid-ul-Fitr (approx., moon-dependent) | D28: Gazetted | E28: Yes | F28: If it falls on Wed 10 Mar, 12 Mar Yatras must move to 2 Apr
A29: 46467 | B29: =TEXT(A29,"dddd") -> Sunday | C29: Holika Dahan | D29: Gazetted | E29: Yes | F29: Sunday
A30: 46468 | B30: =TEXT(A30,"dddd") -> Monday | C30: Holi | D30: Gazetted | E30: Yes | F30: Monday
A31: 46472 | B31: =TEXT(A31,"dddd") -> Friday | C31: Good Friday | D31: Gazetted | E31: Yes | F31: Friday → Yatras on Saturday 27 Mar
A32: 46491 | B32: =TEXT(A32,"dddd") -> Wednesday | C32: Dr. B.R. Ambedkar Jayanti | D32: Gazetted | E32: Yes | F32: Wednesday → 16 Apr skipped
A33: 46492 | B33: =TEXT(A33,"dddd") -> Thursday | C33: Ram Navami (approx.) | D33: Gazetted | E33: Yes

Sheet Route Plan
A1: Gunvatta Yatra UP – 4-Team Route Plan (Friday Yatras)
A2: Ref: SACHIS Circular ABPMJAY/UP-GY/2026-27/161 · Entry Level Certification · Yellow = to fill · Blue km = approx. road distance, verify on maps · Columns Y–Z are helper columns
A4: S.No | B4: Phase / Circuit | C4: Team | D4: Zone | E4: Leg | F4: Mandal | G4: District / Cluster (Host) | H4: Districts covered | I4: No. of districts | J4: Yatra Date | K4: Day | L4: Team on ground by | M4: Travel from | N4: Approx. road km | O4: Calendar check | P4: Earlier GY visit | Q4: Venue (Primary) | R4: Fallback | S4: Refreshment & AV | T4: NABH Faculty | U4: District SPOC (CMO office) | V4: Turnout target | W4: Status | X4: Remarks | Y4: Week Friday | Z4: Key
A5: 1 | B5: Joint Launch | C5: Joint (All 4) | D5: State launch – all 4 members together | E5: J-1 | F5: Lucknow | G5: Lucknow | H5: Lucknow | I5: 1 | J5: 46318 | K5: =TEXT(J5,"dddd") -> Friday | L5: =J5-4 -> 46314 | M5: Team base | O5: =IFERROR(INDEX('Friday Calendar'!$M:$M,MATCH(Y5,'Friday Calendar'!$A:$A,0)),"Not a Friday week – check") -> YATRA DAY | P5: Yes – 20 attended (11 Hot, 2 Warm). Run as follow-up | Q5: CMO Office | R5: QCI Procurement | S5: CMO / QCI – to be locked | V5: 40–50 hospitals | W5: Planned | X5: GRAND LAUNCH – all 4 members. Prep week overlaps Dussehra (19–20 Oct) – team on ground from Wed 21 Oct. Teams split on Sat 24 Oct | Y5: =J5-IF(WEEKDAY(J5,2)=6,1,0) -> 46318 | Z5: =C5&"|"&Y5 -> Joint (All 4)|46318
A6: 2 | B6: First solo Yatra (Oct 2026) | C6: Team 1 – West | D6: Bareilly · Moradabad · Saharanpur · Meerut (NCR) | E6: C0-L1 | F6: Bareilly | G6: Bareilly | H6: Bareilly | I6: 1 | J6: 46325 | K6: =TEXT(J6,"dddd") -> Friday | L6: =J6-4 -> 46321 | M6: Lucknow | N6: 250 | O6: =IFERROR(INDEX('Friday Calendar'!$M:$M,MATCH(Y6,'Friday Calendar'!$A:$A,0)),"Not a Friday week – check") -> YATRA DAY – CAUTION | P6: New district | Q6: CMO Office | R6: QCI Procurement | S6: CMO / QCI – to be locked | V6: 40–50 hospitals | W6: Planned | X6: Only ~2 weeks lead time – CMO letter + SPOC needed this week. Karva Chauth Thu 29 Oct | Y6: =J6-IF(WEEKDAY(J6,2)=6,1,0) -> 46325 | Z6: =C6&"|"&Y6 -> Team 1 – West|46325
A7: 3 | B7: Circuit 1 (Nov–Dec 2026) | C7: Team 1 – West | D7: Bareilly · Moradabad · Saharanpur · Meerut (NCR) | E7: C1-L1 | F7: Bareilly | G7: Shahjahanpur | H7: Shahjahanpur | I7: 1 | J7: 46346 | K7: =TEXT(J7,"dddd") -> Friday | L7: =J7-4 -> 46342 | M7: Team base | O7: =IFERROR(INDEX('Friday Calendar'!$M:$M,MATCH(Y7,'Friday Calendar'!$A:$A,0)),"Not a Friday week – check") -> YATRA DAY | P7: New district | Q7: CMO Office | R7: QCI Procurement | S7: CMO / QCI – to be locked | V7: 40–50 hospitals | W7: Planned | X7: After Diwali break (31 Oct – 15 Nov) | Y7: =J7-IF(WEEKDAY(J7,2)=6,1,0) -> 46346 | Z7: =C7&"|"&Y7 -> Team 1 – West|46346
A8: 4 | B8: Circuit 1 (Nov–Dec 2026) | C8: Team 1 – West | D8: Bareilly · Moradabad · Saharanpur · Meerut (NCR) | E8: C1-L2 | F8: Bareilly | G8: Pilibhit | H8: Pilibhit | I8: 1 | J8: 46353 | K8: =TEXT(J8,"dddd") -> Friday | L8: =J8-4 -> 46349 | M8: Shahjahanpur | N8: 80 | O8: =IFERROR(INDEX('Friday Calendar'!$M:$M,MATCH(Y8,'Friday Calendar'!$A:$A,0)),"Not a Friday week – check") -> YATRA DAY | P8: Yes – 25 attended (no conversions). Run as follow-up | Q8: CMO Office | R8: QCI Procurement | S8: CMO / QCI – to be locked | V8: 40–50 hospitals | W8: Planned | Y8: =J8-IF(WEEKDAY(J8,2)=6,1,0) -> 46353 | Z8: =C8&"|"&Y8 -> Team 1 – West|46353
A9: 5 | B9: Circuit 1 (Nov–Dec 2026) | C9: Team 1 – West | D9: Bareilly · Moradabad · Saharanpur · Meerut (NCR) | E9: C1-L3 | F9: Moradabad | G9: Rampur | H9: Rampur | I9: 1 | J9: 46360 | K9: =TEXT(J9,"dddd") -> Friday | L9: =J9-4 -> 46356 | M9: Pilibhit | N9: 110 | O9: =IFERROR(INDEX('Friday Calendar'!$M:$M,MATCH(Y9,'Friday Calendar'!$A:$A,0)),"Not a Friday week – check") -> YATRA DAY | P9: New district | Q9: CMO Office | R9: QCI Procurement | S9: CMO / QCI – to be locked | V9: 40–50 hospitals | W9: Planned | Y9: =J9-IF(WEEKDAY(J9,2)=6,1,0) -> 46360 | Z9: =C9&"|"&Y9 -> Team 1 – West|46360
A10: 6 | B10: Circuit 1 (Nov–Dec 2026) | C10: Team 1 – West | D10: Bareilly · Moradabad · Saharanpur · Meerut (NCR) | E10: C1-L4 | F10: Moradabad | G10: Moradabad | H10: Moradabad | I10: 1 | J10: 46367 | K10: =TEXT(J10,"dddd") -> Friday | L10: =J10-4 -> 46363 | M10: Rampur | N10: 30 | O10: =IFERROR(INDEX('Friday Calendar'!$M:$M,MATCH(Y10,'Friday Calendar'!$A:$A,0)),"Not a Friday week – check") -> YATRA DAY | P10: New district | Q10: CMO Office | R10: QCI Procurement | S10: CMO / QCI – to be locked | V10: 40–50 hospitals | W10: Planned | Y10: =J10-IF(WEEKDAY(J10,2)=6,1,0) -> 46367 | Z10: =C10&"|"&Y10 -> Team 1 – West|46367
A11: 7 | B11: Reserve | C11: Team 1 – West | D11: Bareilly · Moradabad · Saharanpur · Meerut (NCR) | E11: R-1 | F11: — | G11: RESERVE SLOT | H11: Buffer for a postponed Yatra | I11: 0 | J11: 46374 | K11: =TEXT(J11,"dddd") -> Friday | L11: =J11-4 -> 46370 | M11: — | O11: =IFERROR(INDEX('Friday Calendar'!$M:$M,MATCH(Y11,'Friday Calendar'!$A:$A,0)),"Not a Friday week – check") -> YATRA DAY | P11: — | Q11: — | R11: — | S11: — | T11: — | U11: — | V11: — | W11: Reserve | X11: Year-end reserve – use only for a postponed Yatra | Y11: =J11-IF(WEEKDAY(J11,2)=6,1,0) -> 46374 | Z11: =C11&"|"&Y11 -> Team 1 – West|46374
A12: 8 | B12: Circuit 2 (Jan 2027) | C12: Team 1 – West | D12: Bareilly · Moradabad · Saharanpur · Meerut (NCR) | E12: C2-L1 | F12: Saharanpur | G12: Saharanpur | H12: Saharanpur | I12: 1 | J12: 46395 | K12: =TEXT(J12,"dddd") -> Friday | L12: =J12-4 -> 46391 | M12: Team base | O12: =IFERROR(INDEX('Friday Calendar'!$M:$M,MATCH(Y12,'Friday Calendar'!$A:$A,0)),"Not a Friday week – check") -> YATRA DAY | P12: Yes – 19 attended (1 Hot, 2 Warm). Run as follow-up | Q12: CMO Office | R12: QCI Procurement | S12: CMO / QCI – to be locked | V12: 40–50 hospitals | W12: Planned | Y12: =J12-IF(WEEKDAY(J12,2)=6,1,0) -> 46395 | Z12: =C12&"|"&Y12 -> Team 1 – West|46395
A13: 9 | B13: Circuit 2 (Jan 2027) | C13: Team 1 – West | D13: Bareilly · Moradabad · Saharanpur · Meerut (NCR) | E13: C2-L2 | F13: Saharanpur | G13: Muzaffarnagar | H13: Muzaffarnagar | I13: 1 | J13: 46402 | K13: =TEXT(J13,"dddd") -> Friday | L13: =J13-4 -> 46398 | M13: Saharanpur | N13: 55 | O13: =IFERROR(INDEX('Friday Calendar'!$M:$M,MATCH(Y13,'Friday Calendar'!$A:$A,0)),"Not a Friday week – check") -> YATRA DAY – CAUTION | P13: New district | Q13: CMO Office | R13: QCI Procurement | S13: CMO / QCI – to be locked | V13: 40–50 hospitals | W13: Planned | X13: Makar Sankranti Thu 14 Jan (restricted) – early registrations | Y13: =J13-IF(WEEKDAY(J13,2)=6,1,0) -> 46402 | Z13: =C13&"|"&Y13 -> Team 1 – West|46402
A14: 10 | B14: Circuit 2 (Jan 2027) | C14: Team 1 – West | D14: Bareilly · Moradabad · Saharanpur · Meerut (NCR) | E14: C2-L3 | F14: Saharanpur | G14: Shamli | H14: Shamli | I14: 1 | J14: 46409 | K14: =TEXT(J14,"dddd") -> Friday | L14: =J14-4 -> 46405 | M14: Muzaffarnagar | N14: 40 | O14: =IFERROR(INDEX('Friday Calendar'!$M:$M,MATCH(Y14,'Friday Calendar'!$A:$A,0)),"Not a Friday week – check") -> YATRA DAY | P14: New district | Q14: CMO Office | R14: QCI Procurement | S14: CMO / QCI – to be locked | V14: 40–50 hospitals | W14: Planned | X14: Small district – invite Muzaffarnagar spill-over | Y14: =J14-IF(WEEKDAY(J14,2)=6,1,0) -> 46409 | Z14: =C14&"|"&Y14 -> Team 1 – West|46409
A15: 11 | B15: Circuit 2 (Jan 2027) | C15: Team 1 – West | D15: Bareilly · Moradabad · Saharanpur · Meerut (NCR) | E15: C2-L4 | F15: Meerut | G15: Baghpat | H15: Baghpat | I15: 1 | J15: 46416 | K15: =TEXT(J15,"dddd") -> Friday | L15: =J15-4 -> 46412 | M15: Shamli | N15: 75 | O15: =IFERROR(INDEX('Friday Calendar'!$M:$M,MATCH(Y15,'Friday Calendar'!$A:$A,0)),"Not a Friday week – check") -> YATRA DAY | P15: New district | Q15: CMO Office | R15: QCI Procurement | S15: CMO / QCI – to be locked | V15: 40–50 hospitals | W15: Planned | Y15: =J15-IF(WEEKDAY(J15,2)=6,1,0) -> 46416 | Z15: =C15&"|"&Y15 -> Team 1 – West|46416
A16: 12 | B16: Circuit 3 (Feb 2027) | C16: Team 1 – West | D16: Bareilly · Moradabad · Saharanpur · Meerut (NCR) | E16: C3-L1 | F16: Meerut | G16: Meerut | H16: Meerut | I16: 1 | J16: 46423 | K16: =TEXT(J16,"dddd") -> Friday | L16: =J16-4 -> 46419 | M16: Team base | O16: =IFERROR(INDEX('Friday Calendar'!$M:$M,MATCH(Y16,'Friday Calendar'!$A:$A,0)),"Not a Friday week – check") -> YATRA DAY | P16: Yes – 30 attended (no conversions). Run as follow-up | Q16: CMO Office | R16: QCI Procurement | S16: CMO / QCI – to be locked | V16: 40–50 hospitals | W16: Planned | Y16: =J16-IF(WEEKDAY(J16,2)=6,1,0) -> 46423 | Z16: =C16&"|"&Y16 -> Team 1 – West|46423
A17: 13 | B17: Circuit 3 (Feb 2027) | C17: Team 1 – West | D17: Bareilly · Moradabad · Saharanpur · Meerut (NCR) | E17: C3-L2 | F17: Meerut | G17: Hapur | H17: Hapur | I17: 1 | J17: 46430 | K17: =TEXT(J17,"dddd") -> Friday | L17: =J17-4 -> 46426 | M17: Meerut | N17: 35 | O17: =IFERROR(INDEX('Friday Calendar'!$M:$M,MATCH(Y17,'Friday Calendar'!$A:$A,0)),"Not a Friday week – check") -> YATRA DAY – CAUTION | P17: New district | Q17: CMO Office | R17: QCI Procurement | S17: CMO / QCI – to be locked | V17: 40–50 hospitals | W17: Planned | X17: Basant Panchami Thu 11 Feb (restricted) | Y17: =J17-IF(WEEKDAY(J17,2)=6,1,0) -> 46430 | Z17: =C17&"|"&Y17 -> Team 1 – West|46430
A18: 14 | B18: Circuit 3 (Feb 2027) | C18: Team 1 – West | D18: Bareilly · Moradabad · Saharanpur · Meerut (NCR) | E18: C3-L3 | F18: Meerut | G18: Ghaziabad | H18: Ghaziabad | I18: 1 | J18: 46437 | K18: =TEXT(J18,"dddd") -> Friday | L18: =J18-4 -> 46433 | M18: Hapur | N18: 35 | O18: =IFERROR(INDEX('Friday Calendar'!$M:$M,MATCH(Y18,'Friday Calendar'!$A:$A,0)),"Not a Friday week – check") -> YATRA DAY | P18: New district | Q18: CMO Office | R18: QCI Procurement | S18: CMO / QCI – to be locked | V18: 40–50 hospitals | W18: Planned | Y18: =J18-IF(WEEKDAY(J18,2)=6,1,0) -> 46437 | Z18: =C18&"|"&Y18 -> Team 1 – West|46437
A19: 15 | B19: Circuit 3 (Feb 2027) | C19: Team 1 – West | D19: Bareilly · Moradabad · Saharanpur · Meerut (NCR) | E19: C3-L4 | F19: Meerut | G19: Gautam Buddha Nagar | H19: Gautam Buddha Nagar | I19: 1 | J19: 46444 | K19: =TEXT(J19,"dddd") -> Friday | L19: =J19-4 -> 46440 | M19: Ghaziabad | N19: 35 | O19: =IFERROR(INDEX('Friday Calendar'!$M:$M,MATCH(Y19,'Friday Calendar'!$A:$A,0)),"Not a Friday week – check") -> YATRA DAY | P19: New district | Q19: CMO Office | R19: QCI Procurement | S19: CMO / QCI – to be locked | V19: 40–50 hospitals | W19: Planned | Y19: =J19-IF(WEEKDAY(J19,2)=6,1,0) -> 46444 | Z19: =C19&"|"&Y19 -> Team 1 – West|46444
A20: 16 | B20: Circuit 4 (Mar 2027) | C20: Team 1 – West | D20: Bareilly · Moradabad · Saharanpur · Meerut (NCR) | E20: C4-L1 | F20: Moradabad | G20: Bijnor | H20: Bijnor | I20: 1 | J20: 46451 | K20: =TEXT(J20,"dddd") -> Friday | L20: =J20-4 -> 46447 | M20: Team base | O20: =IFERROR(INDEX('Friday Calendar'!$M:$M,MATCH(Y20,'Friday Calendar'!$A:$A,0)),"Not a Friday week – check") -> YATRA DAY | P20: New district | Q20: CMO Office | R20: QCI Procurement | S20: CMO / QCI – to be locked | V20: 40–50 hospitals | W20: Planned | Y20: =J20-IF(WEEKDAY(J20,2)=6,1,0) -> 46451 | Z20: =C20&"|"&Y20 -> Team 1 – West|46451
A21: 17 | B21: Circuit 4 (Mar 2027) | C21: Team 1 – West | D21: Bareilly · Moradabad · Saharanpur · Meerut (NCR) | E21: C4-L2 | F21: Moradabad | G21: Amroha | H21: Amroha | I21: 1 | J21: 46458 | K21: =TEXT(J21,"dddd") -> Friday | L21: =J21-4 -> 46454 | M21: Bijnor | N21: 70 | O21: =IFERROR(INDEX('Friday Calendar'!$M:$M,MATCH(Y21,'Friday Calendar'!$A:$A,0)),"Not a Friday week – check") -> YATRA DAY | P21: New district | Q21: CMO Office | R21: QCI Procurement | S21: CMO / QCI – to be locked | V21: 40–50 hospitals | W21: Planned | X21: Eid-ul-Fitr ~9 Mar (moon) – confirm | Y21: =J21-IF(WEEKDAY(J21,2)=6,1,0) -> 46458 | Z21: =C21&"|"&Y21 -> Team 1 – West|46458
A22: 18 | B22: Circuit 4 (Mar 2027) | C22: Team 1 – West | D22: Bareilly · Moradabad · Saharanpur · Meerut (NCR) | E22: C4-L3 | F22: Bareilly | G22: Budaun Cluster | H22: Budaun, Sambhal | I22: 2 | J22: 46465 | K22: =TEXT(J22,"dddd") -> Friday | L22: =J22-4 -> 46461 | M22: Amroha | N22: 110 | O22: =IFERROR(INDEX('Friday Calendar'!$M:$M,MATCH(Y22,'Friday Calendar'!$A:$A,0)),"Not a Friday week – check") -> YATRA DAY | P22: New district | Q22: CMO Office | R22: QCI Procurement | S22: CMO / QCI – to be locked | V22: 80–100 hospitals | W22: Planned | X22: Host: Budaun – invite Sambhal via its CMO | Y22: =J22-IF(WEEKDAY(J22,2)=6,1,0) -> 46465 | Z22: =C22&"|"&Y22 -> Team 1 – West|46465
A23: 19 | B23: Reserve | C23: Team 1 – West | D23: Bareilly · Moradabad · Saharanpur · Meerut (NCR) | E23: R-2 | F23: — | G23: RESERVE SLOT | H23: Buffer for a postponed Yatra | I23: 0 | J23: 46473 | K23: =TEXT(J23,"dddd") -> Saturday | L23: =J23-4 -> 46469 | M23: — | O23: =IFERROR(INDEX('Friday Calendar'!$M:$M,MATCH(Y23,'Friday Calendar'!$A:$A,0)),"Not a Friday week – check") -> SATURDAY (Fri holiday) | P23: — | Q23: — | R23: — | S23: — | T23: — | U23: — | V23: — | W23: Reserve | X23: Holi week / Good Friday Saturday – reserve | Y23: =J23-IF(WEEKDAY(J23,2)=6,1,0) -> 46472 | Z23: =C23&"|"&Y23 -> Team 1 – West|46472
A24: 20 | B24: First solo Yatra (Oct 2026) | C24: Team 2 – East | D24: Gorakhpur · Basti · Devipatan · Azamgarh · Varanasi | E24: C0-L1 | F24: Gorakhpur | G24: Gorakhpur | H24: Gorakhpur | I24: 1 | J24: 46325 | K24: =TEXT(J24,"dddd") -> Friday | L24: =J24-4 -> 46321 | M24: Lucknow | N24: 270 | O24: =IFERROR(INDEX('Friday Calendar'!$M:$M,MATCH(Y24,'Friday Calendar'!$A:$A,0)),"Not a Friday week – check") -> YATRA DAY – CAUTION | P24: Yes – 74 attended (6 Won, 24 Hot). Run as follow-up | Q24: CMO Office | R24: QCI Procurement | S24: CMO / QCI – to be locked | V24: 40–50 hospitals | W24: Planned | X24: Already in mobilisation. Karva Chauth Thu 29 Oct | Y24: =J24-IF(WEEKDAY(J24,2)=6,1,0) -> 46325 | Z24: =C24&"|"&Y24 -> Team 2 – East|46325
A25: 21 | B25: Circuit 1 (Nov–Dec 2026) | C25: Team 2 – East | D25: Gorakhpur · Basti · Devipatan · Azamgarh · Varanasi | E25: C1-L1 | F25: Basti | G25: Basti | H25: Basti | I25: 1 | J25: 46346 | K25: =TEXT(J25,"dddd") -> Friday | L25: =J25-4 -> 46342 | M25: Team base | O25: =IFERROR(INDEX('Friday Calendar'!$M:$M,MATCH(Y25,'Friday Calendar'!$A:$A,0)),"Not a Friday week – check") -> YATRA DAY | P25: New district | Q25: CMO Office | R25: QCI Procurement | S25: CMO / QCI – to be locked | V25: 40–50 hospitals | W25: Planned | X25: Chhath 15–16 Nov – reach Tue 17 Nov; push registrations by phone before | Y25: =J25-IF(WEEKDAY(J25,2)=6,1,0) -> 46346 | Z25: =C25&"|"&Y25 -> Team 2 – East|46346
A26: 22 | B26: Circuit 1 (Nov–Dec 2026) | C26: Team 2 – East | D26: Gorakhpur · Basti · Devipatan · Azamgarh · Varanasi | E26: C1-L2 | F26: Basti | G26: Sant Kabir Nagar | H26: Sant Kabir Nagar | I26: 1 | J26: 46353 | K26: =TEXT(J26,"dddd") -> Friday | L26: =J26-4 -> 46349 | M26: Basti | N26: 35 | O26: =IFERROR(INDEX('Friday Calendar'!$M:$M,MATCH(Y26,'Friday Calendar'!$A:$A,0)),"Not a Friday week – check") -> YATRA DAY | P26: New district | Q26: CMO Office | R26: QCI Procurement | S26: CMO / QCI – to be locked | V26: 40–50 hospitals | W26: Planned | Y26: =J26-IF(WEEKDAY(J26,2)=6,1,0) -> 46353 | Z26: =C26&"|"&Y26 -> Team 2 – East|46353
A27: 23 | B27: Circuit 1 (Nov–Dec 2026) | C27: Team 2 – East | D27: Gorakhpur · Basti · Devipatan · Azamgarh · Varanasi | E27: C1-L3 | F27: Gorakhpur | G27: Maharajganj | H27: Maharajganj | I27: 1 | J27: 46360 | K27: =TEXT(J27,"dddd") -> Friday | L27: =J27-4 -> 46356 | M27: Sant Kabir Nagar | N27: 90 | O27: =IFERROR(INDEX('Friday Calendar'!$M:$M,MATCH(Y27,'Friday Calendar'!$A:$A,0)),"Not a Friday week – check") -> YATRA DAY | P27: New district | Q27: CMO Office | R27: QCI Procurement | S27: CMO / QCI – to be locked | V27: 40–50 hospitals | W27: Planned | Y27: =J27-IF(WEEKDAY(J27,2)=6,1,0) -> 46360 | Z27: =C27&"|"&Y27 -> Team 2 – East|46360
A28: 24 | B28: Circuit 1 (Nov–Dec 2026) | C28: Team 2 – East | D28: Gorakhpur · Basti · Devipatan · Azamgarh · Varanasi | E28: C1-L4 | F28: Gorakhpur | G28: Kushi Nagar | H28: Kushi Nagar | I28: 1 | J28: 46367 | K28: =TEXT(J28,"dddd") -> Friday | L28: =J28-4 -> 46363 | M28: Maharajganj | N28: 100 | O28: =IFERROR(INDEX('Friday Calendar'!$M:$M,MATCH(Y28,'Friday Calendar'!$A:$A,0)),"Not a Friday week – check") -> YATRA DAY | P28: New district | Q28: CMO Office | R28: QCI Procurement | S28: CMO / QCI – to be locked | V28: 40–50 hospitals | W28: Planned | Y28: =J28-IF(WEEKDAY(J28,2)=6,1,0) -> 46367 | Z28: =C28&"|"&Y28 -> Team 2 – East|46367
A29: 25 | B29: Reserve | C29: Team 2 – East | D29: Gorakhpur · Basti · Devipatan · Azamgarh · Varanasi | E29: R-1 | F29: — | G29: RESERVE SLOT | H29: Buffer for a postponed Yatra | I29: 0 | J29: 46374 | K29: =TEXT(J29,"dddd") -> Friday | L29: =J29-4 -> 46370 | M29: — | O29: =IFERROR(INDEX('Friday Calendar'!$M:$M,MATCH(Y29,'Friday Calendar'!$A:$A,0)),"Not a Friday week – check") -> YATRA DAY | P29: — | Q29: — | R29: — | S29: — | T29: — | U29: — | V29: — | W29: Reserve | X29: Year-end reserve – use only for a postponed Yatra | Y29: =J29-IF(WEEKDAY(J29,2)=6,1,0) -> 46374 | Z29: =C29&"|"&Y29 -> Team 2 – East|46374
A30: 26 | B30: Circuit 2 (Jan 2027) | C30: Team 2 – East | D30: Gorakhpur · Basti · Devipatan · Azamgarh · Varanasi | E30: C2-L1 | F30: Basti | G30: Siddharth Nagar | H30: Siddharth Nagar | I30: 1 | J30: 46395 | K30: =TEXT(J30,"dddd") -> Friday | L30: =J30-4 -> 46391 | M30: Team base | O30: =IFERROR(INDEX('Friday Calendar'!$M:$M,MATCH(Y30,'Friday Calendar'!$A:$A,0)),"Not a Friday week – check") -> YATRA DAY | P30: New district | Q30: CMO Office | R30: QCI Procurement | S30: CMO / QCI – to be locked | V30: 40–50 hospitals | W30: Planned | Y30: =J30-IF(WEEKDAY(J30,2)=6,1,0) -> 46395 | Z30: =C30&"|"&Y30 -> Team 2 – East|46395
A31: 27 | B31: Circuit 2 (Jan 2027) | C31: Team 2 – East | D31: Gorakhpur · Basti · Devipatan · Azamgarh · Varanasi | E31: C2-L2 | F31: Devipatan | G31: Balrampur Cluster | H31: Balrampur, Shravasti | I31: 2 | J31: 46402 | K31: =TEXT(J31,"dddd") -> Friday | L31: =J31-4 -> 46398 | M31: Siddharth Nagar | N31: 90 | O31: =IFERROR(INDEX('Friday Calendar'!$M:$M,MATCH(Y31,'Friday Calendar'!$A:$A,0)),"Not a Friday week – check") -> YATRA DAY – CAUTION | P31: New district | Q31: CMO Office | R31: QCI Procurement | S31: CMO / QCI – to be locked | V31: 80–100 hospitals | W31: Planned | X31: Host: Balrampur. Khichdi Thu 14 Jan – Gorakhpur avoided | Y31: =J31-IF(WEEKDAY(J31,2)=6,1,0) -> 46402 | Z31: =C31&"|"&Y31 -> Team 2 – East|46402
A32: 28 | B32: Circuit 2 (Jan 2027) | C32: Team 2 – East | D32: Gorakhpur · Basti · Devipatan · Azamgarh · Varanasi | E32: C2-L3 | F32: Devipatan | G32: Bahraich | H32: Bahraich | I32: 1 | J32: 46409 | K32: =TEXT(J32,"dddd") -> Friday | L32: =J32-4 -> 46405 | M32: Balrampur | N32: 80 | O32: =IFERROR(INDEX('Friday Calendar'!$M:$M,MATCH(Y32,'Friday Calendar'!$A:$A,0)),"Not a Friday week – check") -> YATRA DAY | P32: Yes – 15 attended (no conversions). Run as follow-up | Q32: CMO Office | R32: QCI Procurement | S32: CMO / QCI – to be locked | V32: 40–50 hospitals | W32: Planned | Y32: =J32-IF(WEEKDAY(J32,2)=6,1,0) -> 46409 | Z32: =C32&"|"&Y32 -> Team 2 – East|46409
A33: 29 | B33: Circuit 2 (Jan 2027) | C33: Team 2 – East | D33: Gorakhpur · Basti · Devipatan · Azamgarh · Varanasi | E33: C2-L4 | F33: Devipatan | G33: Gonda | H33: Gonda | I33: 1 | J33: 46416 | K33: =TEXT(J33,"dddd") -> Friday | L33: =J33-4 -> 46412 | M33: Bahraich | N33: 60 | O33: =IFERROR(INDEX('Friday Calendar'!$M:$M,MATCH(Y33,'Friday Calendar'!$A:$A,0)),"Not a Friday week – check") -> YATRA DAY | P33: Yes – 21 attended (1 Won). Run as follow-up | Q33: CMO Office | R33: QCI Procurement | S33: CMO / QCI – to be locked | V33: 40–50 hospitals | W33: Planned | Y33: =J33-IF(WEEKDAY(J33,2)=6,1,0) -> 46416 | Z33: =C33&"|"&Y33 -> Team 2 – East|46416
A34: 30 | B34: Circuit 3 (Feb 2027) | C34: Team 2 – East | D34: Gorakhpur · Basti · Devipatan · Azamgarh · Varanasi | E34: C3-L1 | F34: Gorakhpur | G34: Deoria | H34: Deoria | I34: 1 | J34: 46423 | K34: =TEXT(J34,"dddd") -> Friday | L34: =J34-4 -> 46419 | M34: Team base | O34: =IFERROR(INDEX('Friday Calendar'!$M:$M,MATCH(Y34,'Friday Calendar'!$A:$A,0)),"Not a Friday week – check") -> YATRA DAY | P34: Yes – 29 attended (3 Won). Run as follow-up | Q34: CMO Office | R34: QCI Procurement | S34: CMO / QCI – to be locked | V34: 40–50 hospitals | W34: Planned | Y34: =J34-IF(WEEKDAY(J34,2)=6,1,0) -> 46423 | Z34: =C34&"|"&Y34 -> Team 2 – East|46423
A35: 31 | B35: Circuit 3 (Feb 2027) | C35: Team 2 – East | D35: Gorakhpur · Basti · Devipatan · Azamgarh · Varanasi | E35: C3-L2 | F35: Azamgarh | G35: Ballia | H35: Ballia | I35: 1 | J35: 46430 | K35: =TEXT(J35,"dddd") -> Friday | L35: =J35-4 -> 46426 | M35: Deoria | N35: 110 | O35: =IFERROR(INDEX('Friday Calendar'!$M:$M,MATCH(Y35,'Friday Calendar'!$A:$A,0)),"Not a Friday week – check") -> YATRA DAY – CAUTION | P35: New district | Q35: CMO Office | R35: QCI Procurement | S35: CMO / QCI – to be locked | V35: 40–50 hospitals | W35: Planned | X35: Basant Panchami Thu 11 Feb (restricted) | Y35: =J35-IF(WEEKDAY(J35,2)=6,1,0) -> 46430 | Z35: =C35&"|"&Y35 -> Team 2 – East|46430
A36: 32 | B36: Circuit 3 (Feb 2027) | C36: Team 2 – East | D36: Gorakhpur · Basti · Devipatan · Azamgarh · Varanasi | E36: C3-L3 | F36: Azamgarh | G36: Mau | H36: Mau | I36: 1 | J36: 46437 | K36: =TEXT(J36,"dddd") -> Friday | L36: =J36-4 -> 46433 | M36: Ballia | N36: 70 | O36: =IFERROR(INDEX('Friday Calendar'!$M:$M,MATCH(Y36,'Friday Calendar'!$A:$A,0)),"Not a Friday week – check") -> YATRA DAY | P36: New district | Q36: CMO Office | R36: QCI Procurement | S36: CMO / QCI – to be locked | V36: 40–50 hospitals | W36: Planned | Y36: =J36-IF(WEEKDAY(J36,2)=6,1,0) -> 46437 | Z36: =C36&"|"&Y36 -> Team 2 – East|46437
A37: 33 | B37: Circuit 3 (Feb 2027) | C37: Team 2 – East | D37: Gorakhpur · Basti · Devipatan · Azamgarh · Varanasi | E37: C3-L4 | F37: Azamgarh | G37: Azamgarh | H37: Azamgarh | I37: 1 | J37: 46444 | K37: =TEXT(J37,"dddd") -> Friday | L37: =J37-4 -> 46440 | M37: Mau | N37: 45 | O37: =IFERROR(INDEX('Friday Calendar'!$M:$M,MATCH(Y37,'Friday Calendar'!$A:$A,0)),"Not a Friday week – check") -> YATRA DAY | P37: Yes – 11 attended (2 Warm). Run as follow-up | Q37: CMO Office | R37: QCI Procurement | S37: CMO / QCI – to be locked | V37: 40–50 hospitals | W37: Planned | Y37: =J37-IF(WEEKDAY(J37,2)=6,1,0) -> 46444 | Z37: =C37&"|"&Y37 -> Team 2 – East|46444
A38: 34 | B38: Circuit 4 (Mar 2027) | C38: Team 2 – East | D38: Gorakhpur · Basti · Devipatan · Azamgarh · Varanasi | E38: C4-L1 | F38: Varanasi | G38: Ghazipur | H38: Ghazipur | I38: 1 | J38: 46451 | K38: =TEXT(J38,"dddd") -> Friday | L38: =J38-4 -> 46447 | M38: Team base | O38: =IFERROR(INDEX('Friday Calendar'!$M:$M,MATCH(Y38,'Friday Calendar'!$A:$A,0)),"Not a Friday week – check") -> YATRA DAY | P38: New district | Q38: CMO Office | R38: QCI Procurement | S38: CMO / QCI – to be locked | V38: 40–50 hospitals | W38: Planned | Y38: =J38-IF(WEEKDAY(J38,2)=6,1,0) -> 46451 | Z38: =C38&"|"&Y38 -> Team 2 – East|46451
A39: 35 | B39: Circuit 4 (Mar 2027) | C39: Team 2 – East | D39: Gorakhpur · Basti · Devipatan · Azamgarh · Varanasi | E39: C4-L2 | F39: Varanasi | G39: Chandauli | H39: Chandauli | I39: 1 | J39: 46458 | K39: =TEXT(J39,"dddd") -> Friday | L39: =J39-4 -> 46454 | M39: Ghazipur | N39: 75 | O39: =IFERROR(INDEX('Friday Calendar'!$M:$M,MATCH(Y39,'Friday Calendar'!$A:$A,0)),"Not a Friday week – check") -> YATRA DAY | P39: New district | Q39: CMO Office | R39: QCI Procurement | S39: CMO / QCI – to be locked | V39: 40–50 hospitals | W39: Planned | X39: Eid-ul-Fitr ~9 Mar (moon) – confirm | Y39: =J39-IF(WEEKDAY(J39,2)=6,1,0) -> 46458 | Z39: =C39&"|"&Y39 -> Team 2 – East|46458
A40: 36 | B40: Circuit 4 (Mar 2027) | C40: Team 2 – East | D40: Gorakhpur · Basti · Devipatan · Azamgarh · Varanasi | E40: C4-L3 | F40: Varanasi | G40: Varanasi | H40: Varanasi | I40: 1 | J40: 46465 | K40: =TEXT(J40,"dddd") -> Friday | L40: =J40-4 -> 46461 | M40: Chandauli | N40: 30 | O40: =IFERROR(INDEX('Friday Calendar'!$M:$M,MATCH(Y40,'Friday Calendar'!$A:$A,0)),"Not a Friday week – check") -> YATRA DAY | P40: Yes – 6 attended (2 Hot). Run as follow-up | Q40: CMO Office | R40: QCI Procurement | S40: CMO / QCI – to be locked | V40: 40–50 hospitals | W40: Planned | Y40: =J40-IF(WEEKDAY(J40,2)=6,1,0) -> 46465 | Z40: =C40&"|"&Y40 -> Team 2 – East|46465
A41: 37 | B41: Reserve | C41: Team 2 – East | D41: Gorakhpur · Basti · Devipatan · Azamgarh · Varanasi | E41: R-2 | F41: — | G41: RESERVE SLOT | H41: Buffer for a postponed Yatra | I41: 0 | J41: 46473 | K41: =TEXT(J41,"dddd") -> Saturday | L41: =J41-4 -> 46469 | M41: — | O41: =IFERROR(INDEX('Friday Calendar'!$M:$M,MATCH(Y41,'Friday Calendar'!$A:$A,0)),"Not a Friday week – check") -> SATURDAY (Fri holiday) | P41: — | Q41: — | R41: — | S41: — | T41: — | U41: — | V41: — | W41: Reserve | X41: Holi week / Good Friday Saturday – reserve | Y41: =J41-IF(WEEKDAY(J41,2)=6,1,0) -> 46472 | Z41: =C41&"|"&Y41 -> Team 2 – East|46472
...

Sheet Friday Calendar
A1: Friday Calendar – Holiday & Mobilisation Check
A2: Rule: Wed/Thu holiday → SKIP (participant mobilisation) · Friday holiday → SATURDAY · Caution = Yatra allowed, push registrations early · Override (yellow) beats the rule
A4: Friday | B4: Team on ground (Mon) | C4: Wed holiday | D4: Thu holiday | E4: Fri holiday | F4: Sat holiday | G4: Wed/Thu blocks | H4: Fri blocks | I4: Sat blocks | J4: Caution count | K4: Rule result | L4: Planning override | M4: FINAL STATUS | N4: Yatra date to use | O4: Yatras scheduled | P4: NABH faculty needed
A5: 46318 | B5: =A5-4 -> 46314 | C5: =IFERROR(INDEX('UP Holidays'!$C$5:$C$33,MATCH(A5-2,'UP Holidays'!$A$5:$A$33,0)),"") | D5: =IFERROR(INDEX('UP Holidays'!$C$5:$C$33,MATCH(A5-1,'UP Holidays'!$A$5:$A$33,0)),"") | E5: =IFERROR(INDEX('UP Holidays'!$C$5:$C$33,MATCH(A5,'UP Holidays'!$A$5:$A$33,0)),"") | F5: =IFERROR(INDEX('UP Holidays'!$C$5:$C$33,MATCH(A5+1,'UP Holidays'!$A$5:$A$33,0)),"") | G5: =COUNTIFS('UP Holidays'!$A$5:$A$33,A5-2,'UP Holidays'!$E$5:$E$33,"Yes")+COUNTIFS('UP Holidays'!$A$5:$A$33,A5-1,'UP Holidays'!$E$5:$E$33,"Yes") -> 0 | H5: =COUNTIFS('UP Holidays'!$A$5:$A$33,A5,'UP Holidays'!$E$5:$E$33,"Yes") -> 0 | I5: =COUNTIFS('UP Holidays'!$A$5:$A$33,A5+1,'UP Holidays'!$E$5:$E$33,"Yes") -> 0 | J5: =COUNTIFS('UP Holidays'!$A$5:$A$33,A5-2,'UP Holidays'!$E$5:$E$33,"Caution")+COUNTIFS('UP Holidays'!$A$5:$A$33,A5-1,'UP Holidays'!$E$5:$E$33,"Caution")+COUNTIFS('UP Holidays'!$A$5:$A$33,A5,'UP Holidays'!$E$5:$E$33,"Caution") -> 0 | K5: =IF(G5>0,"SKIP – Wed/Thu holiday",IF(H5>0,IF(I5>0,"SKIP – Fri & Sat holiday","SATURDAY (Fri holiday)"),IF(J5>0,"YATRA DAY – CAUTION","YATRA DAY"))) -> YATRA DAY | M5: =IF(L5<>"",L5,K5) -> YATRA DAY | N5: =IF(LEFT(M5,4)="SKIP","",IF(LEFT(M5,8)="SATURDAY",A5+1,A5)) -> 46318 | O5: =COUNTIFS('Route Plan'!$Y$5:$Y$77,A5,'Route Plan'!$I$5:$I$77,">0") -> 1 | P5: =O5 -> 1
A6: 46325 | B6: =A6-4 -> 46321 | C6: =IFERROR(INDEX('UP Holidays'!$C$5:$C$33,MATCH(A6-2,'UP Holidays'!$A$5:$A$33,0)),"") | D6: =IFERROR(INDEX('UP Holidays'!$C$5:$C$33,MATCH(A6-1,'UP Holidays'!$A$5:$A$33,0)),"") -> Karva Chauth | E6: =IFERROR(INDEX('UP Holidays'!$C$5:$C$33,MATCH(A6,'UP Holidays'!$A$5:$A$33,0)),"") | F6: =IFERROR(INDEX('UP Holidays'!$C$5:$C$33,MATCH(A6+1,'UP Holidays'!$A$5:$A$33,0)),"") -> Sardar Patel / Acharya Narendra Dev Jayanti | G6: =COUNTIFS('UP Holidays'!$A$5:$A$33,A6-2,'UP Holidays'!$E$5:$E$33,"Yes")+COUNTIFS('UP Holidays'!$A$5:$A$33,A6-1,'UP Holidays'!$E$5:$E$33,"Yes") -> 0 | H6: =COUNTIFS('UP Holidays'!$A$5:$A$33,A6,'UP Holidays'!$E$5:$E$33,"Yes") -> 0 | I6: =COUNTIFS('UP Holidays'!$A$5:$A$33,A6+1,'UP Holidays'!$E$5:$E$33,"Yes") -> 1 | J6: =COUNTIFS('UP Holidays'!$A$5:$A$33,A6-2,'UP Holidays'!$E$5:$E$33,"Caution")+COUNTIFS('UP Holidays'!$A$5:$A$33,A6-1,'UP Holidays'!$E$5:$E$33,"Caution")+COUNTIFS('UP Holidays'!$A$5:$A$33,A6,'UP Holidays'!$E$5:$E$33,"Caution") -> 1 | K6: =IF(G6>0,"SKIP – Wed/Thu holiday",IF(H6>0,IF(I6>0,"SKIP – Fri & Sat holiday","SATURDAY (Fri holiday)"),IF(J6>0,"YATRA DAY – CAUTION","YATRA DAY"))) -> YATRA DAY – CAUTION | M6: =IF(L6<>"",L6,K6) -> YATRA DAY – CAUTION | N6: =IF(LEFT(M6,4)="SKIP","",IF(LEFT(M6,8)="SATURDAY",A6+1,A6)) -> 46325 | O6: =COUNTIFS('Route Plan'!$Y$5:$Y$77,A6,'Route Plan'!$I$5:$I$77,">0") -> 4 | P6: =O6 -> 4
A7: 46332 | B7: =A7-4 -> 46328 | C7: =IFERROR(INDEX('UP Holidays'!$C$5:$C$33,MATCH(A7-2,'UP Holidays'!$A$5:$A$33,0)),"") | D7: =IFERROR(INDEX('UP Holidays'!$C$5:$C$33,MATCH(A7-1,'UP Holidays'!$A$5:$A$33,0)),"") | E7: =IFERROR(INDEX('UP Holidays'!$C$5:$C$33,MATCH(A7,'UP Holidays'!$A$5:$A$33,0)),"") -> Dhanteras (Diwali week) | F7: =IFERROR(INDEX('UP Holidays'!$C$5:$C$33,MATCH(A7+1,'UP Holidays'!$A$5:$A$33,0)),"") -> Choti Diwali / Narak Chaturdashi | G7: =COUNTIFS('UP Holidays'!$A$5:$A$33,A7-2,'UP Holidays'!$E$5:$E$33,"Yes")+COUNTIFS('UP Holidays'!$A$5:$A$33,A7-1,'UP Holidays'!$E$5:$E$33,"Yes") -> 0 | H7: =COUNTIFS('UP Holidays'!$A$5:$A$33,A7,'UP Holidays'!$E$5:$E$33,"Yes") -> 1 | I7: =COUNTIFS('UP Holidays'!$A$5:$A$33,A7+1,'UP Holidays'!$E$5:$E$33,"Yes") -> 1 | J7: =COUNTIFS('UP Holidays'!$A$5:$A$33,A7-2,'UP Holidays'!$E$5:$E$33,"Caution")+COUNTIFS('UP Holidays'!$A$5:$A$33,A7-1,'UP Holidays'!$E$5:$E$33,"Caution")+COUNTIFS('UP Holidays'!$A$5:$A$33,A7,'UP Holidays'!$E$5:$E$33,"Caution") -> 0 | K7: =IF(G7>0,"SKIP – Wed/Thu holiday",IF(H7>0,IF(I7>0,"SKIP – Fri & Sat holiday","SATURDAY (Fri holiday)"),IF(J7>0,"YATRA DAY – CAUTION","YATRA DAY"))) -> SKIP – Fri & Sat holiday | M7: =IF(L7<>"",L7,K7) -> SKIP – Fri & Sat holiday | N7: =IF(LEFT(M7,4)="SKIP","",IF(LEFT(M7,8)="SATURDAY",A7+1,A7)) | O7: =COUNTIFS('Route Plan'!$Y$5:$Y$77,A7,'Route Plan'!$I$5:$I$77,">0") -> 0 | P7: =O7 -> 0
A8: 46339 | B8: =A8-4 -> 46335 | C8: =IFERROR(INDEX('UP Holidays'!$C$5:$C$33,MATCH(A8-2,'UP Holidays'!$A$5:$A$33,0)),"") -> Bhai Dooj / Chitragupta Jayanti | D8: =IFERROR(INDEX('UP Holidays'!$C$5:$C$33,MATCH(A8-1,'UP Holidays'!$A$5:$A$33,0)),"") | E8: =IFERROR(INDEX('UP Holidays'!$C$5:$C$33,MATCH(A8,'UP Holidays'!$A$5:$A$33,0)),"") | F8: =IFERROR(INDEX('UP Holidays'!$C$5:$C$33,MATCH(A8+1,'UP Holidays'!$A$5:$A$33,0)),"") | G8: =COUNTIFS('UP Holidays'!$A$5:$A$33,A8-2,'UP Holidays'!$E$5:$E$33,"Yes")+COUNTIFS('UP Holidays'!$A$5:$A$33,A8-1,'UP Holidays'!$E$5:$E$33,"Yes") -> 1 | H8: =COUNTIFS('UP Holidays'!$A$5:$A$33,A8,'UP Holidays'!$E$5:$E$33,"Yes") -> 0 | I8: =COUNTIFS('UP Holidays'!$A$5:$A$33,A8+1,'UP Holidays'!$E$5:$E$33,"Yes") -> 0 | J8: =COUNTIFS('UP Holidays'!$A$5:$A$33,A8-2,'UP Holidays'!$E$5:$E$33,"Caution")+COUNTIFS('UP Holidays'!$A$5:$A$33,A8-1,'UP Holidays'!$E$5:$E$33,"Caution")+COUNTIFS('UP Holidays'!$A$5:$A$33,A8,'UP Holidays'!$E$5:$E$33,"Caution") -> 0 | K8: =IF(G8>0,"SKIP – Wed/Thu holiday",IF(H8>0,IF(I8>0,"SKIP – Fri & Sat holiday","SATURDAY (Fri holiday)"),IF(J8>0,"YATRA DAY – CAUTION","YATRA DAY"))) -> SKIP – Wed/Thu holiday | M8: =IF(L8<>"",L8,K8) -> SKIP – Wed/Thu holiday | N8: =IF(LEFT(M8,4)="SKIP","",IF(LEFT(M8,8)="SATURDAY",A8+1,A8)) | O8: =COUNTIFS('Route Plan'!$Y$5:$Y$77,A8,'Route Plan'!$I$5:$I$77,">0") -> 0 | P8: =O8 -> 0
A9: 46346 | B9: =A9-4 -> 46342 | C9: =IFERROR(INDEX('UP Holidays'!$C$5:$C$33,MATCH(A9-2,'UP Holidays'!$A$5:$A$33,0)),"") | D9: =IFERROR(INDEX('UP Holidays'!$C$5:$C$33,MATCH(A9-1,'UP Holidays'!$A$5:$A$33,0)),"") | E9: =IFERROR(INDEX('UP Holidays'!$C$5:$C$33,MATCH(A9,'UP Holidays'!$A$5:$A$33,0)),"") | F9: =IFERROR(INDEX('UP Holidays'!$C$5:$C$33,MATCH(A9+1,'UP Holidays'!$A$5:$A$33,0)),"") | G9: =COUNTIFS('UP Holidays'!$A$5:$A$33,A9-2,'UP Holidays'!$E$5:$E$33,"Yes")+COUNTIFS('UP Holidays'!$A$5:$A$33,A9-1,'UP Holidays'!$E$5:$E$33,"Yes") -> 0 | H9: =COUNTIFS('UP Holidays'!$A$5:$A$33,A9,'UP Holidays'!$E$5:$E$33,"Yes") -> 0 | I9: =COUNTIFS('UP Holidays'!$A$5:$A$33,A9+1,'UP Holidays'!$E$5:$E$33,"Yes") -> 0 | J9: =COUNTIFS('UP Holidays'!$A$5:$A$33,A9-2,'UP Holidays'!$E$5:$E$33,"Caution")+COUNTIFS('UP Holidays'!$A$5:$A$33,A9-1,'UP Holidays'!$E$5:$E$33,"Caution")+COUNTIFS('UP Holidays'!$A$5:$A$33,A9,'UP Holidays'!$E$5:$E$33,"Caution") -> 0 | K9: =IF(G9>0,"SKIP – Wed/Thu holiday",IF(H9>0,IF(I9>0,"SKIP – Fri & Sat holiday","SATURDAY (Fri holiday)"),IF(J9>0,"YATRA DAY – CAUTION","YATRA DAY"))) -> YATRA DAY | M9: =IF(L9<>"",L9,K9) -> YATRA DAY | N9: =IF(LEFT(M9,4)="SKIP","",IF(LEFT(M9,8)="SATURDAY",A9+1,A9)) -> 46346 | O9: =COUNTIFS('Route Plan'!$Y$5:$Y$77,A9,'Route Plan'!$I$5:$I$77,">0") -> 4 | P9: =O9 -> 4
A10: 46353 | B10: =A10-4 -> 46349 | C10: =IFERROR(INDEX('UP Holidays'!$C$5:$C$33,MATCH(A10-2,'UP Holidays'!$A$5:$A$33,0)),"") | D10: =IFERROR(INDEX('UP Holidays'!$C$5:$C$33,MATCH(A10-1,'UP Holidays'!$A$5:$A$33,0)),"") | E10: =IFERROR(INDEX('UP Holidays'!$C$5:$C$33,MATCH(A10,'UP Holidays'!$A$5:$A$33,0)),"") | F10: =IFERROR(INDEX('UP Holidays'!$C$5:$C$33,MATCH(A10+1,'UP Holidays'!$A$5:$A$33,0)),"") | G10: =COUNTIFS('UP Holidays'!$A$5:$A$33,A10-2,'UP Holidays'!$E$5:$E$33,"Yes")+COUNTIFS('UP Holidays'!$A$5:$A$33,A10-1,'UP Holidays'!$E$5:$E$33,"Yes") -> 0 | H10: =COUNTIFS('UP Holidays'!$A$5:$A$33,A10,'UP Holidays'!$E$5:$E$33,"Yes") -> 0 | I10: =COUNTIFS('UP Holidays'!$A$5:$A$33,A10+1,'UP Holidays'!$E$5:$E$33,"Yes") -> 0 | J10: =COUNTIFS('UP Holidays'!$A$5:$A$33,A10-2,'UP Holidays'!$E$5:$E$33,"Caution")+COUNTIFS('UP Holidays'!$A$5:$A$33,A10-1,'UP Holidays'!$E$5:$E$33,"Caution")+COUNTIFS('UP Holidays'!$A$5:$A$33,A10,'UP Holidays'!$E$5:$E$33,"Caution") -> 0 | K10: =IF(G10>0,"SKIP – Wed/Thu holiday",IF(H10>0,IF(I10>0,"SKIP – Fri & Sat holiday","SATURDAY (Fri holiday)"),IF(J10>0,"YATRA DAY – CAUTION","YATRA DAY"))) -> YATRA DAY | M10: =IF(L10<>"",L10,K10) -> YATRA DAY | N10: =IF(LEFT(M10,4)="SKIP","",IF(LEFT(M10,8)="SATURDAY",A10+1,A10)) -> 46353 | O10: =COUNTIFS('Route Plan'!$Y$5:$Y$77,A10,'Route Plan'!$I$5:$I$77,">0") -> 4 | P10: =O10 -> 4
A11: 46360 | B11: =A11-4 -> 46356 | C11: =IFERROR(INDEX('UP Holidays'!$C$5:$C$33,MATCH(A11-2,'UP Holidays'!$A$5:$A$33,0)),"") | D11: =IFERROR(INDEX('UP Holidays'!$C$5:$C$33,MATCH(A11-1,'UP Holidays'!$A$5:$A$33,0)),"") | E11: =IFERROR(INDEX('UP Holidays'!$C$5:$C$33,MATCH(A11,'UP Holidays'!$A$5:$A$33,0)),"") | F11: =IFERROR(INDEX('UP Holidays'!$C$5:$C$33,MATCH(A11+1,'UP Holidays'!$A$5:$A$33,0)),"") | G11: =COUNTIFS('UP Holidays'!$A$5:$A$33,A11-2,'UP Holidays'!$E$5:$E$33,"Yes")+COUNTIFS('UP Holidays'!$A$5:$A$33,A11-1,'UP Holidays'!$E$5:$E$33,"Yes") -> 0 | H11: =COUNTIFS('UP Holidays'!$A$5:$A$33,A11,'UP Holidays'!$E$5:$E$33,"Yes") -> 0 | I11: =COUNTIFS('UP Holidays'!$A$5:$A$33,A11+1,'UP Holidays'!$E$5:$E$33,"Yes") -> 0 | J11: =COUNTIFS('UP Holidays'!$A$5:$A$33,A11-2,'UP Holidays'!$E$5:$E$33,"Caution")+COUNTIFS('UP Holidays'!$A$5:$A$33,A11-1,'UP Holidays'!$E$5:$E$33,"Caution")+COUNTIFS('UP Holidays'!$A$5:$A$33,A11,'UP Holidays'!$E$5:$E$33,"Caution") -> 0 | K11: =IF(G11>0,"SKIP – Wed/Thu holiday",IF(H11>0,IF(I11>0,"SKIP – Fri & Sat holiday","SATURDAY (Fri holiday)"),IF(J11>0,"YATRA DAY – CAUTION","YATRA DAY"))) -> YATRA DAY | M11: =IF(L11<>"",L11,K11) -> YATRA DAY | N11: =IF(LEFT(M11,4)="SKIP","",IF(LEFT(M11,8)="SATURDAY",A11+1,A11)) -> 46360 | O11: =COUNTIFS('Route Plan'!$Y$5:$Y$77,A11,'Route Plan'!$I$5:$I$77,">0") -> 4 | P11: =O11 -> 4
A12: 46367 | B12: =A12-4 -> 46363 | C12: =IFERROR(INDEX('UP Holidays'!$C$5:$C$33,MATCH(A12-2,'UP Holidays'!$A$5:$A$33,0)),"") | D12: =IFERROR(INDEX('UP Holidays'!$C$5:$C$33,MATCH(A12-1,'UP Holidays'!$A$5:$A$33,0)),"") | E12: =IFERROR(INDEX('UP Holidays'!$C$5:$C$33,MATCH(A12,'UP Holidays'!$A$5:$A$33,0)),"") | F12: =IFERROR(INDEX('UP Holidays'!$C$5:$C$33,MATCH(A12+1,'UP Holidays'!$A$5:$A$33,0)),"") | G12: =COUNTIFS('UP Holidays'!$A$5:$A$33,A12-2,'UP Holidays'!$E$5:$E$33,"Yes")+COUNTIFS('UP Holidays'!$A$5:$A$33,A12-1,'UP Holidays'!$E$5:$E$33,"Yes") -> 0 | H12: =COUNTIFS('UP Holidays'!$A$5:$A$33,A12,'UP Holidays'!$E$5:$E$33,"Yes") -> 0 | I12: =COUNTIFS('UP Holidays'!$A$5:$A$33,A12+1,'UP Holidays'!$E$5:$E$33,"Yes") -> 0 | J12: =COUNTIFS('UP Holidays'!$A$5:$A$33,A12-2,'UP Holidays'!$E$5:$E$33,"Caution")+COUNTIFS('UP Holidays'!$A$5:$A$33,A12-1,'UP Holidays'!$E$5:$E$33,"Caution")+COUNTIFS('UP Holidays'!$A$5:$A$33,A12,'UP Holidays'!$E$5:$E$33,"Caution") -> 0 | K12: =IF(G12>0,"SKIP – Wed/Thu holiday",IF(H12>0,IF(I12>0,"SKIP – Fri & Sat holiday","SATURDAY (Fri holiday)"),IF(J12>0,"YATRA DAY – CAUTION","YATRA DAY"))) -> YATRA DAY | M12: =IF(L12<>"",L12,K12) -> YATRA DAY | N12: =IF(LEFT(M12,4)="SKIP","",IF(LEFT(M12,8)="SATURDAY",A12+1,A12)) -> 46367 | O12: =COUNTIFS('Route Plan'!$Y$5:$Y$77,A12,'Route Plan'!$I$5:$I$77,">0") -> 4 | P12: =O12 -> 4
A13: 46374 | B13: =A13-4 -> 46370 | C13: =IFERROR(INDEX('UP Holidays'!$C$5:$C$33,MATCH(A13-2,'UP Holidays'!$A$5:$A$33,0)),"") | D13: =IFERROR(INDEX('UP Holidays'!$C$5:$C$33,MATCH(A13-1,'UP Holidays'!$A$5:$A$33,0)),"") | E13: =IFERROR(INDEX('UP Holidays'!$C$5:$C$33,MATCH(A13,'UP Holidays'!$A$5:$A$33,0)),"") | F13: =IFERROR(INDEX('UP Holidays'!$C$5:$C$33,MATCH(A13+1,'UP Holidays'!$A$5:$A$33,0)),"") | G13: =COUNTIFS('UP Holidays'!$A$5:$A$33,A13-2,'UP Holidays'!$E$5:$E$33,"Yes")+COUNTIFS('UP Holidays'!$A$5:$A$33,A13-1,'UP Holidays'!$E$5:$E$33,"Yes") -> 0 | H13: =COUNTIFS('UP Holidays'!$A$5:$A$33,A13,'UP Holidays'!$E$5:$E$33,"Yes") -> 0 | I13: =COUNTIFS('UP Holidays'!$A$5:$A$33,A13+1,'UP Holidays'!$E$5:$E$33,"Yes") -> 0 | J13: =COUNTIFS('UP Holidays'!$A$5:$A$33,A13-2,'UP Holidays'!$E$5:$E$33,"Caution")+COUNTIFS('UP Holidays'!$A$5:$A$33,A13-1,'UP Holidays'!$E$5:$E$33,"Caution")+COUNTIFS('UP Holidays'!$A$5:$A$33,A13,'UP Holidays'!$E$5:$E$33,"Caution") -> 0 | K13: =IF(G13>0,"SKIP – Wed/Thu holiday",IF(H13>0,IF(I13>0,"SKIP – Fri & Sat holiday","SATURDAY (Fri holiday)"),IF(J13>0,"YATRA DAY – CAUTION","YATRA DAY"))) -> YATRA DAY | M13: =IF(L13<>"",L13,K13) -> YATRA DAY | N13: =IF(LEFT(M13,4)="SKIP","",IF(LEFT(M13,8)="SATURDAY",A13+1,A13)) -> 46374 | O13: =COUNTIFS('Route Plan'!$Y$5:$Y$77,A13,'Route Plan'!$I$5:$I$77,">0") -> 0 | P13: =O13 -> 0
A14: 46381 | B14: =A14-4 -> 46377 | C14: =IFERROR(INDEX('UP Holidays'!$C$5:$C$33,MATCH(A14-2,'UP Holidays'!$A$5:$A$33,0)),"") -> Chaudhary Charan Singh Jayanti / Hazrat Ali Jayanti | D14: =IFERROR(INDEX('UP Holidays'!$C$5:$C$33,MATCH(A14-1,'UP Holidays'!$A$5:$A$33,0)),"") -> Christmas Eve | E14: =IFERROR(INDEX('UP Holidays'!$C$5:$C$33,MATCH(A14,'UP Holidays'!$A$5:$A$33,0)),"") -> Christmas | F14: =IFERROR(INDEX('UP Holidays'!$C$5:$C$33,MATCH(A14+1,'UP Holidays'!$A$5:$A$33,0)),"") | G14: =COUNTIFS('UP Holidays'!$A$5:$A$33,A14-2,'UP Holidays'!$E$5:$E$33,"Yes")+COUNTIFS('UP Holidays'!$A$5:$A$33,A14-1,'UP Holidays'!$E$5:$E$33,"Yes") -> 1 | H14: =COUNTIFS('UP Holidays'!$A$5:$A$33,A14,'UP Holidays'!$E$5:$E$33,"Yes") -> 1 | I14: =COUNTIFS('UP Holidays'!$A$5:$A$33,A14+1,'UP Holidays'!$E$5:$E$33,"Yes") -> 0 | J14: =COUNTIFS('UP Holidays'!$A$5:$A$33,A14-2,'UP Holidays'!$E$5:$E$33,"Caution")+COUNTIFS('UP Holidays'!$A$5:$A$33,A14-1,'UP Holidays'!$E$5:$E$33,"Caution")+COUNTIFS('UP Holidays'!$A$5:$A$33,A14,'UP Holidays'!$E$5:$E$33,"Caution") -> 1 | K14: =IF(G14>0,"SKIP – Wed/Thu holiday",IF(H14>0,IF(I14>0,"SKIP – Fri & Sat holiday","SATURDAY (Fri holiday)"),IF(J14>0,"YATRA DAY – CAUTION","YATRA DAY"))) -> SKIP – Wed/Thu holiday | M14: =IF(L14<>"",L14,K14) -> SKIP – Wed/Thu holiday | N14: =IF(LEFT(M14,4)="SKIP","",IF(LEFT(M14,8)="SATURDAY",A14+1,A14)) | O14: =COUNTIFS('Route Plan'!$Y$5:$Y$77,A14,'Route Plan'!$I$5:$I$77,">0") -> 0 | P14: =O14 -> 0
A15: 46388 | B15: =A15-4 -> 46384 | C15: =IFERROR(INDEX('UP Holidays'!$C$5:$C$33,MATCH(A15-2,'UP Holidays'!$A$5:$A$33,0)),"") | D15: =IFERROR(INDEX('UP Holidays'!$C$5:$C$33,MATCH(A15-1,'UP Holidays'!$A$5:$A$33,0)),"") | E15: =IFERROR(INDEX('UP Holidays'!$C$5:$C$33,MATCH(A15,'UP Holidays'!$A$5:$A$33,0)),"") -> New Year's Day | F15: =IFERROR(INDEX('UP Holidays'!$C$5:$C$33,MATCH(A15+1,'UP Holidays'!$A$5:$A$33,0)),"") | G15: =COUNTIFS('UP Holidays'!$A$5:$A$33,A15-2,'UP Holidays'!$E$5:$E$33,"Yes")+COUNTIFS('UP Holidays'!$A$5:$A$33,A15-1,'UP Holidays'!$E$5:$E$33,"Yes") -> 0 | H15: =COUNTIFS('UP Holidays'!$A$5:$A$33,A15,'UP Holidays'!$E$5:$E$33,"Yes") -> 0 | I15: =COUNTIFS('UP Holidays'!$A$5:$A$33,A15+1,'UP Holidays'!$E$5:$E$33,"Yes") -> 0 | J15: =COUNTIFS('UP Holidays'!$A$5:$A$33,A15-2,'UP Holidays'!$E$5:$E$33,"Caution")+COUNTIFS('UP Holidays'!$A$5:$A$33,A15-1,'UP Holidays'!$E$5:$E$33,"Caution")+COUNTIFS('UP Holidays'!$A$5:$A$33,A15,'UP Holidays'!$E$5:$E$33,"Caution") -> 1 | K15: =IF(G15>0,"SKIP – Wed/Thu holiday",IF(H15>0,IF(I15>0,"SKIP – Fri & Sat holiday","SATURDAY (Fri holiday)"),IF(J15>0,"YATRA DAY – CAUTION","YATRA DAY"))) -> YATRA DAY – CAUTION | L15: SKIP – year-end break (19 Dec–3 Jan) | M15: =IF(L15<>"",L15,K15) -> SKIP – year-end break (19 Dec–3 Jan) | N15: =IF(LEFT(M15,4)="SKIP","",IF(LEFT(M15,8)="SATURDAY",A15+1,A15)) | O15: =COUNTIFS('Route Plan'!$Y$5:$Y$77,A15,'Route Plan'!$I$5:$I$77,">0") -> 0 | P15: =O15 -> 0
A16: 46395 | B16: =A16-4 -> 46391 | C16: =IFERROR(INDEX('UP Holidays'!$C$5:$C$33,MATCH(A16-2,'UP Holidays'!$A$5:$A$33,0)),"") | D16: =IFERROR(INDEX('UP Holidays'!$C$5:$C$33,MATCH(A16-1,'UP Holidays'!$A$5:$A$33,0)),"") | E16: =IFERROR(INDEX('UP Holidays'!$C$5:$C$33,MATCH(A16,'UP Holidays'!$A$5:$A$33,0)),"") | F16: =IFERROR(INDEX('UP Holidays'!$C$5:$C$33,MATCH(A16+1,'UP Holidays'!$A$5:$A$33,0)),"") | G16: =COUNTIFS('UP Holidays'!$A$5:$A$33,A16-2,'UP Holidays'!$E$5:$E$33,"Yes")+COUNTIFS('UP Holidays'!$A$5:$A$33,A16-1,'UP Holidays'!$E$5:$E$33,"Yes") -> 0 | H16: =COUNTIFS('UP Holidays'!$A$5:$A$33,A16,'UP Holidays'!$E$5:$E$33,"Yes") -> 0 | I16: =COUNTIFS('UP Holidays'!$A$5:$A$33,A16+1,'UP Holidays'!$E$5:$E$33,"Yes") -> 0 | J16: =COUNTIFS('UP Holidays'!$A$5:$A$33,A16-2,'UP Holidays'!$E$5:$E$33,"Caution")+COUNTIFS('UP Holidays'!$A$5:$A$33,A16-1,'UP Holidays'!$E$5:$E$33,"Caution")+COUNTIFS('UP Holidays'!$A$5:$A$33,A16,'UP Holidays'!$E$5:$E$33,"Caution") -> 0 | K16: =IF(G16>0,"SKIP – Wed/Thu holiday",IF(H16>0,IF(I16>0,"SKIP – Fri & Sat holiday","SATURDAY (Fri holiday)"),IF(J16>0,"YATRA DAY – CAUTION","YATRA DAY"))) -> YATRA DAY | M16: =IF(L16<>"",L16,K16) -> YATRA DAY | N16: =IF(LEFT(M16,4)="SKIP","",IF(LEFT(M16,8)="SATURDAY",A16+1,A16)) -> 46395 | O16: =COUNTIFS('Route Plan'!$Y$5:$Y$77,A16,'Route Plan'!$I$5:$I$77,">0") -> 4 | P16: =O16 -> 4
A17: 46402 | B17: =A17-4 -> 46398 | C17: =IFERROR(INDEX('UP Holidays'!$C$5:$C$33,MATCH(A17-2,'UP Holidays'!$A$5:$A$33,0)),"") | D17: =IFERROR(INDEX('UP Holidays'!$C$5:$C$33,MATCH(A17-1,'UP Holidays'!$A$5:$A$33,0)),"") -> Makar Sankranti / Khichdi | E17: =IFERROR(INDEX('UP Holidays'!$C$5:$C$33,MATCH(A17,'UP Holidays'!$A$5:$A$33,0)),"") | F17: =IFERROR(INDEX('UP Holidays'!$C$5:$C$33,MATCH(A17+1,'UP Holidays'!$A$5:$A$33,0)),"") | G17: =COUNTIFS('UP Holidays'!$A$5:$A$33,A17-2,'UP Holidays'!$E$5:$E$33,"Yes")+COUNTIFS('UP Holidays'!$A$5:$A$33,A17-1,'UP Holidays'!$E$5:$E$33,"Yes") -> 0 | H17: =COUNTIFS('UP Holidays'!$A$5:$A$33,A17,'UP Holidays'!$E$5:$E$33,"Yes") -> 0 | I17: =COUNTIFS('UP Holidays'!$A$5:$A$33,A17+1,'UP Holidays'!$E$5:$E$33,"Yes") -> 0 | J17: =COUNTIFS('UP Holidays'!$A$5:$A$33,A17-2,'UP Holidays'!$E$5:$E$33,"Caution")+COUNTIFS('UP Holidays'!$A$5:$A$33,A17-1,'UP Holidays'!$E$5:$E$33,"Caution")+COUNTIFS('UP Holidays'!$A$5:$A$33,A17,'UP Holidays'!$E$5:$E$33,"Caution") -> 1 | K17: =IF(G17>0,"SKIP – Wed/Thu holiday",IF(H17>0,IF(I17>0,"SKIP – Fri & Sat holiday","SATURDAY (Fri holiday)"),IF(J17>0,"YATRA DAY – CAUTION","YATRA DAY"))) -> YATRA DAY – CAUTION | M17: =IF(L17<>"",L17,K17) -> YATRA DAY – CAUTION | N17: =IF(LEFT(M17,4)="SKIP","",IF(LEFT(M17,8)="SATURDAY",A17+1,A17)) -> 46402 | O17: =COUNTIFS('Route Plan'!$Y$5:$Y$77,A17,'Route Plan'!$I$5:$I$77,">0") -> 4 | P17: =O17 -> 4
A18: 46409 | B18: =A18-4 -> 46405 | C18: =IFERROR(INDEX('UP Holidays'!$C$5:$C$33,MATCH(A18-2,'UP Holidays'!$A$5:$A$33,0)),"") | D18: =IFERROR(INDEX('UP Holidays'!$C$5:$C$33,MATCH(A18-1,'UP Holidays'!$A$5:$A$33,0)),"") | E18: =IFERROR(INDEX('UP Holidays'!$C$5:$C$33,MATCH(A18,'UP Holidays'!$A$5:$A$33,0)),"") | F18: =IFERROR(INDEX('UP Holidays'!$C$5:$C$33,MATCH(A18+1,'UP Holidays'!$A$5:$A$33,0)),"") | G18: =COUNTIFS('UP Holidays'!$A$5:$A$33,A18-2,'UP Holidays'!$E$5:$E$33,"Yes")+COUNTIFS('UP Holidays'!$A$5:$A$33,A18-1,'UP Holidays'!$E$5:$E$33,"Yes") -> 0 | H18: =COUNTIFS('UP Holidays'!$A$5:$A$33,A18,'UP Holidays'!$E$5:$E$33,"Yes") -> 0 | I18: =COUNTIFS('UP Holidays'!$A$5:$A$33,A18+1,'UP Holidays'!$E$5:$E$33,"Yes") -> 0 | J18: =COUNTIFS('UP Holidays'!$A$5:$A$33,A18-2,'UP Holidays'!$E$5:$E$33,"Caution")+COUNTIFS('UP Holidays'!$A$5:$A$33,A18-1,'UP Holidays'!$E$5:$E$33,"Caution")+COUNTIFS('UP Holidays'!$A$5:$A$33,A18,'UP Holidays'!$E$5:$E$33,"Caution") -> 0 | K18: =IF(G18>0,"SKIP – Wed/Thu holiday",IF(H18>0,IF(I18>0,"SKIP – Fri & Sat holiday","SATURDAY (Fri holiday)"),IF(J18>0,"YATRA DAY – CAUTION","YATRA DAY"))) -> YATRA DAY | M18: =IF(L18<>"",L18,K18) -> YATRA DAY | N18: =IF(LEFT(M18,4)="SKIP","",IF(LEFT(M18,8)="SATURDAY",A18+1,A18)) -> 46409 | O18: =COUNTIFS('Route Plan'!$Y$5:$Y$77,A18,'Route Plan'!$I$5:$I$77,">0") -> 4 | P18: =O18 -> 4
