Workbook

Sheet All Yatras
A1: Phase | B1: Yatra # | C1: Event Date | D1: Day | E1: Time | F1: Rath / Mode | G1: Cluster | H1: Role | I1: Mandal | J1: District | K1: Zone | L1: Tier | M1: Visit Type | N1: PM-JAY Universe | O1: NABH Total | P1: Certified | Q1: Accredited | R1: Potential Gap | S1: % Potential | T1: Yatras Conducted | U1: Attended | V1: Won | W1: Application in Progress | X1: Hot | Y1: Warm
A2: TOTAL | B2: 63 yatras | J2: 75 districts | N2: =SUM(N3:N77) -> 3650 | O2: =SUM(O3:O77) -> 1404 | P2: =SUM(P3:P77) -> 955 | Q2: =SUM(Q3:Q77) -> 449 | R2: =SUM(R3:R77) -> 2246 | S2: =IF(N2=0,0,R2/N2) -> 0.61534247 | T2: =SUM(T3:T77) -> 25 | U2: =SUM(U3:U77) -> 509 | V2: =SUM(V3:V77) -> 22 | W2: =SUM(W3:W77) -> 22 | X2: =SUM(X3:X77) -> 71 | Y2: =SUM(Y3:Y77) -> 25
A3: Phase 1 | B3: 1 | C3: 46304 | D3: Friday | E3: 4 PM - 8 PM | F3: Launch (Rath A + B) | H3: Host | I3: Gorakhpur | J3: Gorakhpur | K3: Eastern UP | L3: Tier 3 | M3: Follow-up | N3: 211 | O3: 68 | P3: 58 | Q3: 10 | R3: 143 | S3: =IF(N3=0,0,R3/N3) -> 0.67772512 | T3: 3 | U3: 74 | V3: 6 | W3: 1 | X3: 24 | Y3: 3
A4: Phase 1 | B4: 2 | C4: 46309 | D4: Wednesday | E4: 4 PM - 8 PM | F4: Rath A | H4: Host | I4: Bareilly | J4: Bareilly | K4: Western UP | L4: Tier 3 | M4: New | N4: 211 | O4: 90 | P4: 57 | Q4: 33 | R4: 121 | S4: =IF(N4=0,0,R4/N4) -> 0.57345972
A5: Phase 1 | B5: 3 | C5: 46309 | D5: Wednesday | E5: 4 PM - 8 PM | F5: Rath B | H5: Host | I5: Gorakhpur | J5: Kushi Nagar | K5: Eastern UP | L5: Tier 3 | M5: New | N5: 47 | O5: 3 | P5: 3 | Q5: 0 | R5: 44 | S5: =IF(N5=0,0,R5/N5) -> 0.93617021
A6: Phase 1 | B6: 4 | C6: 46311 | D6: Friday | E6: 4 PM - 8 PM | F6: Rath A | H6: Host | I6: Moradabad | J6: Moradabad | K6: Western UP | L6: Tier 3 | M6: New | N6: 103 | O6: 40 | P6: 26 | Q6: 14 | R6: 63 | S6: =IF(N6=0,0,R6/N6) -> 0.61165049
A7: Phase 1 | B7: 5 | C7: 46311 | D7: Friday | E7: 4 PM - 8 PM | F7: Rath B | H7: Host | I7: Gorakhpur | J7: Maharajganj | K7: Eastern UP | L7: Tier 3 | M7: New | N7: 24 | O7: 1 | P7: 1 | Q7: 0 | R7: 23 | S7: =IF(N7=0,0,R7/N7) -> 0.95833333
A8: Phase 1 | B8: 6 | C8: 46318 | D8: Friday | E8: 4 PM - 8 PM | F8: Rath A | H8: Host | I8: Moradabad | J8: Bijnor | K8: Western UP | L8: Tier 3 | M8: New | N8: 91 | O8: 21 | P8: 21 | Q8: 0 | R8: 70 | S8: =IF(N8=0,0,R8/N8) -> 0.76923077
A9: Phase 1 | B9: 7 | C9: 46318 | D9: Friday | E9: 4 PM - 8 PM | F9: Rath B | H9: Host | I9: Basti | J9: Sant Kabir Nagar | K9: Eastern UP | L9: Tier 3 | M9: New | N9: 46 | O9: 7 | P9: 7 | Q9: 0 | R9: 39 | S9: =IF(N9=0,0,R9/N9) -> 0.84782609
A10: Phase 1 | B10: 8 | C10: 46323 | D10: Wednesday | E10: 4 PM - 8 PM | F10: Rath A | H10: Host | I10: Saharanpur | J10: Muzaffarnagar | K10: Western UP | L10: Tier 3 | M10: New | N10: 44 | O10: 21 | P10: 19 | Q10: 2 | R10: 23 | S10: =IF(N10=0,0,R10/N10) -> 0.52272727
A11: Phase 1 | B11: 9 | C11: 46323 | D11: Wednesday | E11: 4 PM - 8 PM | F11: Rath B | H11: Host | I11: Basti | J11: Basti | K11: Eastern UP | L11: Tier 3 | M11: New | N11: 78 | O11: 11 | P11: 10 | Q11: 1 | R11: 67 | S11: =IF(N11=0,0,R11/N11) -> 0.85897436
A12: Phase 1 | B12: 10 | C12: 46325 | D12: Friday | E12: 4 PM - 8 PM | F12: Rath A | H12: Host | I12: Saharanpur | J12: Saharanpur | K12: Western UP | L12: Tier 3 | M12: Follow-up | N12: 80 | O12: 34 | P12: 32 | Q12: 2 | R12: 46 | S12: =IF(N12=0,0,R12/N12) -> 0.575 | T12: 2 | U12: 19 | V12: 0 | W12: 0 | X12: 1 | Y12: 2
A13: Phase 1 | B13: 11 | C13: 46325 | D13: Friday | E13: 4 PM - 8 PM | F13: Rath B | H13: Host | I13: Ayodhya | J13: Barabanki | K13: Eastern UP | L13: Tier 3 | M13: New | N13: 42 | O13: 4 | P13: 3 | Q13: 1 | R13: 38 | S13: =IF(N13=0,0,R13/N13) -> 0.9047619
A14: Phase 1 | B14: 12 | C14: 46330 | D14: Wednesday | E14: 4 PM - 8 PM | F14: Rath A | H14: Host | I14: Saharanpur | J14: Shamli | K14: Western UP | L14: Tier 3 | M14: New | N14: 39 | O14: 9 | P14: 8 | Q14: 1 | R14: 30 | S14: =IF(N14=0,0,R14/N14) -> 0.76923077
A15: Phase 1 | B15: 13 | C15: 46330 | D15: Wednesday | E15: 4 PM - 8 PM | F15: Rath B | H15: Host | I15: Lucknow | J15: Lakhimpur Kheri | K15: Central UP | L15: Tier 3 | M15: New | N15: 21 | O15: 1 | P15: 1 | Q15: 0 | R15: 20 | S15: =IF(N15=0,0,R15/N15) -> 0.95238095
A16: Phase 1 | B16: 14 | C16: 46339 | D16: Friday | E16: 4 PM - 8 PM | F16: Rath A | H16: Host | I16: Meerut | J16: Bulandshahar | K16: Western UP | L16: Tier 3 | M16: New | N16: 100 | O16: 49 | P16: 41 | Q16: 8 | R16: 51 | S16: =IF(N16=0,0,R16/N16) -> 0.51
A17: Phase 1 | B17: 15 | C17: 46339 | D17: Friday | E17: 4 PM - 8 PM | F17: Rath B | H17: Host | I17: Prayagraj | J17: Prayagraj | K17: Eastern UP | L17: Tier 3 | M17: Follow-up | N17: 179 | O17: 45 | P17: 23 | Q17: 22 | R17: 134 | S17: =IF(N17=0,0,R17/N17) -> 0.74860335 | T17: 1 | U17: 30 | V17: 0 | W17: 8 | X17: 7 | Y17: 0
A18: Phase 1 | B18: 16 | C18: 46344 | D18: Wednesday | E18: 4 PM - 8 PM | F18: Rath A | H18: Host | I18: Meerut | J18: Hapur | K18: Western UP | L18: Tier 3 | M18: New | N18: 37 | O18: 6 | P18: 5 | Q18: 1 | R18: 31 | S18: =IF(N18=0,0,R18/N18) -> 0.83783784
A19: Phase 1 | B19: 17 | C19: 46344 | D19: Wednesday | E19: 4 PM - 8 PM | F19: Rath B | H19: Host | I19: Vindhyachal | J19: Mirzapur | K19: Eastern UP | L19: Tier 3 | M19: Follow-up | N19: 33 | O19: 8 | P19: 5 | Q19: 3 | R19: 25 | S19: =IF(N19=0,0,R19/N19) -> 0.75757576 | T19: 1 | U19: 27 | V19: 0 | W19: 0 | X19: 0 | Y19: 0
A20: Phase 1 | B20: 18 | C20: 46346 | D20: Friday | E20: 4 PM - 8 PM | F20: Rath A | H20: Host | I20: Aligarh | J20: Aligarh | K20: Western UP | L20: Tier 3 | M20: New | N20: 70 | O20: 29 | P20: 24 | Q20: 5 | R20: 41 | S20: =IF(N20=0,0,R20/N20) -> 0.58571429
A21: Phase 1 | B21: 19 | C21: 46346 | D21: Friday | E21: 4 PM - 8 PM | F21: Rath B | H21: Host | I21: Vindhyachal | J21: Bhadohi | K21: Eastern UP | L21: Tier 3 | M21: New | N21: 35 | O21: 4 | P21: 4 | Q21: 0 | R21: 31 | S21: =IF(N21=0,0,R21/N21) -> 0.88571429
A22: Phase 1 | B22: 20 | C22: 46351 | D22: Wednesday | E22: 4 PM - 8 PM | F22: Rath A | H22: Host | I22: Kanpur | J22: Kanpur Nagar | K22: Central UP | L22: Tier 2 | M22: New | N22: 194 | O22: 90 | P22: 60 | Q22: 30 | R22: 104 | S22: =IF(N22=0,0,R22/N22) -> 0.53608247
A23: Phase 1 | B23: 21 | C23: 46351 | D23: Wednesday | E23: 4 PM - 8 PM | F23: Rath B | H23: Host | I23: Varanasi | J23: Chandauli | K23: Eastern UP | L23: Tier 3 | M23: New | N23: 62 | O23: 9 | P23: 9 | Q23: 0 | R23: 53 | S23: =IF(N23=0,0,R23/N23) -> 0.85483871
A24: Phase 1 | B24: 22 | C24: 46353 | D24: Friday | E24: 4 PM - 8 PM | F24: Rath A | H24: Host | I24: Jhansi | J24: Jhansi | K24: Bundelkhand (South UP) | L24: Tier 3 | M24: Follow-up | N24: 71 | O24: 34 | P24: 31 | Q24: 3 | R24: 37 | S24: =IF(N24=0,0,R24/N24) -> 0.52112676 | T24: 1 | U24: 41 | V24: 0 | W24: 8 | X24: 14 | Y24: 0
A25: Phase 1 | B25: 23 | C25: 46353 | D25: Friday | E25: 4 PM - 8 PM | F25: Rath B | H25: Host | I25: Azamgarh | J25: Mau | K25: Eastern UP | L25: Tier 3 | M25: New | N25: 36 | O25: 4 | P25: 2 | Q25: 2 | R25: 32 | S25: =IF(N25=0,0,R25/N25) -> 0.88888889
A26: Phase 2 | B26: 1 | C26: 46393 | D26: Wednesday | E26: 4 PM - 8 PM | F26: Rath A | H26: Host | I26: Varanasi | J26: Jaunpur | K26: Eastern UP | L26: Tier 3 | M26: Follow-up | N26: 58 | O26: 9 | P26: 9 | Q26: 0 | R26: 49 | S26: =IF(N26=0,0,R26/N26) -> 0.84482759 | T26: 1 | U26: 22 | V26: 2 | W26: 1 | X26: 3 | Y26: 2
A27: Phase 2 | B27: 2 | C27: 46393 | D27: Wednesday | E27: 4 PM - 8 PM | F27: Rath B | H27: Host | I27: Meerut | J27: Meerut | K27: Western UP | L27: Tier 3 | M27: Follow-up | N27: 129 | O27: 67 | P27: 40 | Q27: 27 | R27: 62 | S27: =IF(N27=0,0,R27/N27) -> 0.48062016 | T27: 1 | U27: 30 | V27: 0 | W27: 0 | X27: 0 | Y27: 0
A28: Phase 2 | B28: 3 | C28: 46395 | D28: Friday | E28: 4 PM - 8 PM | F28: Rath A | H28: Host | I28: Gorakhpur | J28: Deoria | K28: Eastern UP | L28: Tier 3 | M28: Follow-up | N28: 32 | O28: 5 | P28: 5 | Q28: 0 | R28: 27 | S28: =IF(N28=0,0,R28/N28) -> 0.84375 | T28: 1 | U28: 29 | V28: 3 | W28: 0 | X28: 3 | Y28: 1
A29: Phase 2 | B29: 4 | C29: 46395 | D29: Friday | E29: 4 PM - 8 PM | F29: Rath B | H29: Host | I29: Agra | J29: Agra | K29: Western UP | L29: Tier 2 | M29: Follow-up | N29: 89 | O29: 56 | P29: 45 | Q29: 11 | R29: 33 | S29: =IF(N29=0,0,R29/N29) -> 0.37078652 | T29: 2 | U29: 14 | V29: 3 | W29: 0 | X29: 2 | Y29: 3
A30: Phase 2 | B30: 5 | C30: 46400 | D30: Wednesday | E30: 4 PM - 8 PM | F30: Rath A | H30: Host | I30: Ayodhya | J30: Ambedkar Nagar | K30: Eastern UP | L30: Tier 3 | M30: Follow-up | N30: 30 | O30: 3 | P30: 3 | Q30: 0 | R30: 27 | S30: =IF(N30=0,0,R30/N30) -> 0.9 | T30: 1 | U30: 32 | V30: 4 | W30: 2 | X30: 1 | Y30: 3
A31: Phase 2 | B31: 6 | C31: 46400 | D31: Wednesday | E31: 4 PM - 8 PM | F31: Rath B | H31: Host | I31: Agra | J31: Mathura | K31: Western UP | L31: Tier 3 | M31: Follow-up | N31: 70 | O31: 25 | P31: 21 | Q31: 4 | R31: 45 | S31: =IF(N31=0,0,R31/N31) -> 0.64285714 | T31: 2 | U31: 42 | V31: 0 | W31: 0 | X31: 0 | Y31: 0
A32: Phase 2 | B32: 7 | C32: 46402 | D32: Friday | E32: 4 PM - 8 PM | F32: Rath A | H32: Host | I32: Ayodhya | J32: Ayodhya | K32: Eastern UP | L32: Tier 3 | M32: Follow-up | N32: 30 | O32: 7 | P32: 6 | Q32: 1 | R32: 23 | S32: =IF(N32=0,0,R32/N32) -> 0.76666667 | T32: 1 | U32: 32 | V32: 2 | W32: 1 | X32: 2 | Y32: 1
A33: Phase 2 | B33: 8 | C33: 46402 | D33: Friday | E33: 4 PM - 8 PM | F33: Rath B | H33: Host | I33: Bareilly | J33: Pilibhit | K33: Western UP | L33: Tier 3 | M33: Follow-up | N33: 27 | O33: 4 | P33: 3 | Q33: 1 | R33: 23 | S33: =IF(N33=0,0,R33/N33) -> 0.85185185 | T33: 1 | U33: 25 | V33: 0 | W33: 0 | X33: 0 | Y33: 0
A34: Phase 2 | B34: 9 | C34: 46407 | D34: Wednesday | E34: 4 PM - 8 PM | F34: Rath A | H34: Host | I34: Ayodhya | J34: Sultanpur | K34: Eastern UP | L34: Tier 3 | M34: Follow-up | N34: 37 | O34: 7 | P34: 7 | Q34: 0 | R34: 30 | S34: =IF(N34=0,0,R34/N34) -> 0.81081081 | T34: 1 | U34: 35 | V34: 1 | W34: 1 | X34: 1 | Y34: 6
A35: Phase 2 | B35: 10 | C35: 46407 | D35: Wednesday | E35: 4 PM - 8 PM | F35: Rath B | H35: Host | I35: Bareilly | J35: Shahjahanpur | K35: Western UP | L35: Tier 3 | M35: New | N35: 32 | O35: 11 | P35: 10 | Q35: 1 | R35: 21 | S35: =IF(N35=0,0,R35/N35) -> 0.65625
A36: Phase 2 | B36: 11 | C36: 46409 | D36: Friday | E36: 4 PM - 8 PM | F36: Rath A | H36: Host | I36: Ayodhya | J36: Amethi | K36: Eastern UP | L36: Tier 3 | M36: New | N36: 24 | O36: 3 | P36: 3 | Q36: 0 | R36: 21 | S36: =IF(N36=0,0,R36/N36) -> 0.875
A37: Phase 2 | B37: 12 | C37: 46409 | D37: Friday | E37: 4 PM - 8 PM | F37: Rath B | H37: Host | I37: Moradabad | J37: Rampur | K37: Western UP | L37: Tier 3 | M37: New | N37: 23 | O37: 5 | P37: 4 | Q37: 1 | R37: 18 | S37: =IF(N37=0,0,R37/N37) -> 0.7826087
A38: Phase 2 | B38: 13 | C38: 46414 | D38: Wednesday | E38: 4 PM - 8 PM | F38: Rath A | H38: Host | I38: Devipatan | J38: Gonda | K38: Eastern UP | L38: Tier 3 | M38: Follow-up | N38: 29 | O38: 4 | P38: 4 | Q38: 0 | R38: 25 | S38: =IF(N38=0,0,R38/N38) -> 0.86206897 | T38: 1 | U38: 0 | V38: 1 | W38: 0 | X38: 0 | Y38: 0
A39: Phase 2 | B39: 14 | C39: 46414 | D39: Wednesday | E39: 4 PM - 8 PM | F39: Rath B | H39: Host | I39: Moradabad | J39: Amroha | K39: Western UP | L39: Tier 3 | M39: New | N39: 23 | O39: 7 | P39: 4 | Q39: 3 | R39: 16 | S39: =IF(N39=0,0,R39/N39) -> 0.69565217
A40: Phase 2 | B40: 15 | C40: 46416 | D40: Friday | E40: 4 PM - 8 PM | F40: Rath A | H40: Host | I40: Varanasi | J40: Varanasi | K40: Eastern UP | L40: Tier 3 | M40: Follow-up | N40: 231 | O40: 90 | P40: 57 | Q40: 33 | R40: 141 | S40: =IF(N40=0,0,R40/N40) -> 0.61038961 | T40: 1 | U40: 6 | V40: 0 | W40: 0 | X40: 2 | Y40: 0
...

Sheet Phase 1 (Oct-Nov 2026)
A1: Yatra # | B1: Event Date | C1: Day | D1: Time | E1: Rath | F1: Mandal | G1: District | H1: Zone | I1: Tier | J1: Visit Type | K1: PM-JAY Universe | L1: NABH Total | M1: Certified | N1: Accredited | O1: Potential Gap | P1: % Potential | Q1: Yatras Conducted | R1: Attended | S1: Won | T1: Application in Progress | U1: Hot | V1: Warm
A2: TOTAL | G2: 23 districts | K2: =SUM(K3:K25) -> 1854 | L2: =SUM(L3:L25) -> 588 | M2: =SUM(M3:M25) -> 450 | N2: =SUM(N3:N25) -> 138 | O2: =SUM(O3:O25) -> 1266 | P2: =IF(K2=0,0,O2/K2) -> 0.6828479 | Q2: =SUM(Q3:Q25) -> 8 | R2: =SUM(R3:R25) -> 191 | S2: =SUM(S3:S25) -> 6 | T2: =SUM(T3:T25) -> 17 | U2: =SUM(U3:U25) -> 46 | V2: =SUM(V3:V25) -> 5
A3: 1 | B3: 46304 | C3: Friday | D3: 4 PM - 8 PM | E3: Launch (Rath A + B) | F3: Gorakhpur | G3: Gorakhpur | H3: Eastern UP | I3: Tier 3 | J3: Follow-up | K3: 211 | L3: 68 | M3: 58 | N3: 10 | O3: 143 | P3: =IF(K3=0,0,O3/K3) -> 0.67772512 | Q3: 3 | R3: 74 | S3: 6 | T3: 1 | U3: 24 | V3: 3
A4: 2 | B4: 46309 | C4: Wednesday | D4: 4 PM - 8 PM | E4: Rath A | F4: Bareilly | G4: Bareilly | H4: Western UP | I4: Tier 3 | J4: New | K4: 211 | L4: 90 | M4: 57 | N4: 33 | O4: 121 | P4: =IF(K4=0,0,O4/K4) -> 0.57345972
A5: 3 | B5: 46309 | C5: Wednesday | D5: 4 PM - 8 PM | E5: Rath B | F5: Gorakhpur | G5: Kushi Nagar | H5: Eastern UP | I5: Tier 3 | J5: New | K5: 47 | L5: 3 | M5: 3 | N5: 0 | O5: 44 | P5: =IF(K5=0,0,O5/K5) -> 0.93617021
A6: 4 | B6: 46311 | C6: Friday | D6: 4 PM - 8 PM | E6: Rath A | F6: Moradabad | G6: Moradabad | H6: Western UP | I6: Tier 3 | J6: New | K6: 103 | L6: 40 | M6: 26 | N6: 14 | O6: 63 | P6: =IF(K6=0,0,O6/K6) -> 0.61165049
A7: 5 | B7: 46311 | C7: Friday | D7: 4 PM - 8 PM | E7: Rath B | F7: Gorakhpur | G7: Maharajganj | H7: Eastern UP | I7: Tier 3 | J7: New | K7: 24 | L7: 1 | M7: 1 | N7: 0 | O7: 23 | P7: =IF(K7=0,0,O7/K7) -> 0.95833333
A8: 6 | B8: 46318 | C8: Friday | D8: 4 PM - 8 PM | E8: Rath A | F8: Moradabad | G8: Bijnor | H8: Western UP | I8: Tier 3 | J8: New | K8: 91 | L8: 21 | M8: 21 | N8: 0 | O8: 70 | P8: =IF(K8=0,0,O8/K8) -> 0.76923077
A9: 7 | B9: 46318 | C9: Friday | D9: 4 PM - 8 PM | E9: Rath B | F9: Basti | G9: Sant Kabir Nagar | H9: Eastern UP | I9: Tier 3 | J9: New | K9: 46 | L9: 7 | M9: 7 | N9: 0 | O9: 39 | P9: =IF(K9=0,0,O9/K9) -> 0.84782609
A10: 8 | B10: 46323 | C10: Wednesday | D10: 4 PM - 8 PM | E10: Rath A | F10: Saharanpur | G10: Muzaffarnagar | H10: Western UP | I10: Tier 3 | J10: New | K10: 44 | L10: 21 | M10: 19 | N10: 2 | O10: 23 | P10: =IF(K10=0,0,O10/K10) -> 0.52272727
A11: 9 | B11: 46323 | C11: Wednesday | D11: 4 PM - 8 PM | E11: Rath B | F11: Basti | G11: Basti | H11: Eastern UP | I11: Tier 3 | J11: New | K11: 78 | L11: 11 | M11: 10 | N11: 1 | O11: 67 | P11: =IF(K11=0,0,O11/K11) -> 0.85897436
A12: 10 | B12: 46325 | C12: Friday | D12: 4 PM - 8 PM | E12: Rath A | F12: Saharanpur | G12: Saharanpur | H12: Western UP | I12: Tier 3 | J12: Follow-up | K12: 80 | L12: 34 | M12: 32 | N12: 2 | O12: 46 | P12: =IF(K12=0,0,O12/K12) -> 0.575 | Q12: 2 | R12: 19 | S12: 0 | T12: 0 | U12: 1 | V12: 2
A13: 11 | B13: 46325 | C13: Friday | D13: 4 PM - 8 PM | E13: Rath B | F13: Ayodhya | G13: Barabanki | H13: Eastern UP | I13: Tier 3 | J13: New | K13: 42 | L13: 4 | M13: 3 | N13: 1 | O13: 38 | P13: =IF(K13=0,0,O13/K13) -> 0.9047619
A14: 12 | B14: 46330 | C14: Wednesday | D14: 4 PM - 8 PM | E14: Rath A | F14: Saharanpur | G14: Shamli | H14: Western UP | I14: Tier 3 | J14: New | K14: 39 | L14: 9 | M14: 8 | N14: 1 | O14: 30 | P14: =IF(K14=0,0,O14/K14) -> 0.76923077
A15: 13 | B15: 46330 | C15: Wednesday | D15: 4 PM - 8 PM | E15: Rath B | F15: Lucknow | G15: Lakhimpur Kheri | H15: Central UP | I15: Tier 3 | J15: New | K15: 21 | L15: 1 | M15: 1 | N15: 0 | O15: 20 | P15: =IF(K15=0,0,O15/K15) -> 0.95238095
A16: 14 | B16: 46339 | C16: Friday | D16: 4 PM - 8 PM | E16: Rath A | F16: Meerut | G16: Bulandshahar | H16: Western UP | I16: Tier 3 | J16: New | K16: 100 | L16: 49 | M16: 41 | N16: 8 | O16: 51 | P16: =IF(K16=0,0,O16/K16) -> 0.51
A17: 15 | B17: 46339 | C17: Friday | D17: 4 PM - 8 PM | E17: Rath B | F17: Prayagraj | G17: Prayagraj | H17: Eastern UP | I17: Tier 3 | J17: Follow-up | K17: 179 | L17: 45 | M17: 23 | N17: 22 | O17: 134 | P17: =IF(K17=0,0,O17/K17) -> 0.74860335 | Q17: 1 | R17: 30 | S17: 0 | T17: 8 | U17: 7 | V17: 0
A18: 16 | B18: 46344 | C18: Wednesday | D18: 4 PM - 8 PM | E18: Rath A | F18: Meerut | G18: Hapur | H18: Western UP | I18: Tier 3 | J18: New | K18: 37 | L18: 6 | M18: 5 | N18: 1 | O18: 31 | P18: =IF(K18=0,0,O18/K18) -> 0.83783784
A19: 17 | B19: 46344 | C19: Wednesday | D19: 4 PM - 8 PM | E19: Rath B | F19: Vindhyachal | G19: Mirzapur | H19: Eastern UP | I19: Tier 3 | J19: Follow-up | K19: 33 | L19: 8 | M19: 5 | N19: 3 | O19: 25 | P19: =IF(K19=0,0,O19/K19) -> 0.75757576 | Q19: 1 | R19: 27 | S19: 0 | T19: 0 | U19: 0 | V19: 0
A20: 18 | B20: 46346 | C20: Friday | D20: 4 PM - 8 PM | E20: Rath A | F20: Aligarh | G20: Aligarh | H20: Western UP | I20: Tier 3 | J20: New | K20: 70 | L20: 29 | M20: 24 | N20: 5 | O20: 41 | P20: =IF(K20=0,0,O20/K20) -> 0.58571429
A21: 19 | B21: 46346 | C21: Friday | D21: 4 PM - 8 PM | E21: Rath B | F21: Vindhyachal | G21: Bhadohi | H21: Eastern UP | I21: Tier 3 | J21: New | K21: 35 | L21: 4 | M21: 4 | N21: 0 | O21: 31 | P21: =IF(K21=0,0,O21/K21) -> 0.88571429
A22: 20 | B22: 46351 | C22: Wednesday | D22: 4 PM - 8 PM | E22: Rath A | F22: Kanpur | G22: Kanpur Nagar | H22: Central UP | I22: Tier 2 | J22: New | K22: 194 | L22: 90 | M22: 60 | N22: 30 | O22: 104 | P22: =IF(K22=0,0,O22/K22) -> 0.53608247
A23: 21 | B23: 46351 | C23: Wednesday | D23: 4 PM - 8 PM | E23: Rath B | F23: Varanasi | G23: Chandauli | H23: Eastern UP | I23: Tier 3 | J23: New | K23: 62 | L23: 9 | M23: 9 | N23: 0 | O23: 53 | P23: =IF(K23=0,0,O23/K23) -> 0.85483871
A24: 22 | B24: 46353 | C24: Friday | D24: 4 PM - 8 PM | E24: Rath A | F24: Jhansi | G24: Jhansi | H24: Bundelkhand (South UP) | I24: Tier 3 | J24: Follow-up | K24: 71 | L24: 34 | M24: 31 | N24: 3 | O24: 37 | P24: =IF(K24=0,0,O24/K24) -> 0.52112676 | Q24: 1 | R24: 41 | S24: 0 | T24: 8 | U24: 14 | V24: 0
A25: 23 | B25: 46353 | C25: Friday | D25: 4 PM - 8 PM | E25: Rath B | F25: Azamgarh | G25: Mau | H25: Eastern UP | I25: Tier 3 | J25: New | K25: 36 | L25: 4 | M25: 2 | N25: 2 | O25: 32 | P25: =IF(K25=0,0,O25/K25) -> 0.88888889
A27: Source: UP GY district schedule finalised 15 Sep 2026; hospital figures from 'Updated District List data.xlsx' -> (VF) Final Sheet. 23 workshops, 12 event days, two Raths in parallel on every date after the 09 Oct Gorakhpur launch. All sessions: Entry Level Certification, 4 PM - 8 PM.

Sheet Phase 2 (Jan-Mar 2027)
A1: Yatra # | B1: Event Date | C1: Day | D1: Time | E1: Rath | F1: Mandal | G1: District | H1: Zone | I1: Tier | J1: Visit Type | K1: PM-JAY Universe | L1: NABH Total | M1: Certified | N1: Accredited | O1: Potential Gap | P1: % Potential | Q1: Yatras Conducted | R1: Attended | S1: Won | T1: Application in Progress | U1: Hot | V1: Warm
A2: TOTAL | G2: 33 districts | K2: =SUM(K3:K35) -> 1645 | L2: =SUM(L3:L35) -> 794 | M2: =SUM(M3:M35) -> 484 | N2: =SUM(N3:N35) -> 310 | O2: =SUM(O3:O35) -> 851 | P2: =IF(K2=0,0,O2/K2) -> 0.51732523 | Q2: =SUM(Q3:Q35) -> 16 | R2: =SUM(R3:R35) -> 298 | S2: =SUM(S3:S35) -> 16 | T2: =SUM(T3:T35) -> 5 | U2: =SUM(U3:U35) -> 25 | V2: =SUM(V3:V35) -> 20
A3: 1 | B3: 46393 | C3: Wednesday | D3: 4 PM - 8 PM | E3: Rath A | F3: Varanasi | G3: Jaunpur | H3: Eastern UP | I3: Tier 3 | J3: Follow-up | K3: 58 | L3: 9 | M3: 9 | N3: 0 | O3: 49 | P3: =IF(K3=0,0,O3/K3) -> 0.84482759 | Q3: 1 | R3: 22 | S3: 2 | T3: 1 | U3: 3 | V3: 2
A4: 2 | B4: 46393 | C4: Wednesday | D4: 4 PM - 8 PM | E4: Rath B | F4: Meerut | G4: Meerut | H4: Western UP | I4: Tier 3 | J4: Follow-up | K4: 129 | L4: 67 | M4: 40 | N4: 27 | O4: 62 | P4: =IF(K4=0,0,O4/K4) -> 0.48062016 | Q4: 1 | R4: 30 | S4: 0 | T4: 0 | U4: 0 | V4: 0
A5: 3 | B5: 46395 | C5: Friday | D5: 4 PM - 8 PM | E5: Rath A | F5: Gorakhpur | G5: Deoria | H5: Eastern UP | I5: Tier 3 | J5: Follow-up | K5: 32 | L5: 5 | M5: 5 | N5: 0 | O5: 27 | P5: =IF(K5=0,0,O5/K5) -> 0.84375 | Q5: 1 | R5: 29 | S5: 3 | T5: 0 | U5: 3 | V5: 1
A6: 4 | B6: 46395 | C6: Friday | D6: 4 PM - 8 PM | E6: Rath B | F6: Agra | G6: Agra | H6: Western UP | I6: Tier 2 | J6: Follow-up | K6: 89 | L6: 56 | M6: 45 | N6: 11 | O6: 33 | P6: =IF(K6=0,0,O6/K6) -> 0.37078652 | Q6: 2 | R6: 14 | S6: 3 | T6: 0 | U6: 2 | V6: 3
A7: 5 | B7: 46400 | C7: Wednesday | D7: 4 PM - 8 PM | E7: Rath A | F7: Ayodhya | G7: Ambedkar Nagar | H7: Eastern UP | I7: Tier 3 | J7: Follow-up | K7: 30 | L7: 3 | M7: 3 | N7: 0 | O7: 27 | P7: =IF(K7=0,0,O7/K7) -> 0.9 | Q7: 1 | R7: 32 | S7: 4 | T7: 2 | U7: 1 | V7: 3
A8: 6 | B8: 46400 | C8: Wednesday | D8: 4 PM - 8 PM | E8: Rath B | F8: Agra | G8: Mathura | H8: Western UP | I8: Tier 3 | J8: Follow-up | K8: 70 | L8: 25 | M8: 21 | N8: 4 | O8: 45 | P8: =IF(K8=0,0,O8/K8) -> 0.64285714 | Q8: 2 | R8: 42 | S8: 0 | T8: 0 | U8: 0 | V8: 0
A9: 7 | B9: 46402 | C9: Friday | D9: 4 PM - 8 PM | E9: Rath A | F9: Ayodhya | G9: Ayodhya | H9: Eastern UP | I9: Tier 3 | J9: Follow-up | K9: 30 | L9: 7 | M9: 6 | N9: 1 | O9: 23 | P9: =IF(K9=0,0,O9/K9) -> 0.76666667 | Q9: 1 | R9: 32 | S9: 2 | T9: 1 | U9: 2 | V9: 1
A10: 8 | B10: 46402 | C10: Friday | D10: 4 PM - 8 PM | E10: Rath B | F10: Bareilly | G10: Pilibhit | H10: Western UP | I10: Tier 3 | J10: Follow-up | K10: 27 | L10: 4 | M10: 3 | N10: 1 | O10: 23 | P10: =IF(K10=0,0,O10/K10) -> 0.85185185 | Q10: 1 | R10: 25 | S10: 0 | T10: 0 | U10: 0 | V10: 0
A11: 9 | B11: 46407 | C11: Wednesday | D11: 4 PM - 8 PM | E11: Rath A | F11: Ayodhya | G11: Sultanpur | H11: Eastern UP | I11: Tier 3 | J11: Follow-up | K11: 37 | L11: 7 | M11: 7 | N11: 0 | O11: 30 | P11: =IF(K11=0,0,O11/K11) -> 0.81081081 | Q11: 1 | R11: 35 | S11: 1 | T11: 1 | U11: 1 | V11: 6
A12: 10 | B12: 46407 | C12: Wednesday | D12: 4 PM - 8 PM | E12: Rath B | F12: Bareilly | G12: Shahjahanpur | H12: Western UP | I12: Tier 3 | J12: New | K12: 32 | L12: 11 | M12: 10 | N12: 1 | O12: 21 | P12: =IF(K12=0,0,O12/K12) -> 0.65625
A13: 11 | B13: 46409 | C13: Friday | D13: 4 PM - 8 PM | E13: Rath A | F13: Ayodhya | G13: Amethi | H13: Eastern UP | I13: Tier 3 | J13: New | K13: 24 | L13: 3 | M13: 3 | N13: 0 | O13: 21 | P13: =IF(K13=0,0,O13/K13) -> 0.875
A14: 12 | B14: 46409 | C14: Friday | D14: 4 PM - 8 PM | E14: Rath B | F14: Moradabad | G14: Rampur | H14: Western UP | I14: Tier 3 | J14: New | K14: 23 | L14: 5 | M14: 4 | N14: 1 | O14: 18 | P14: =IF(K14=0,0,O14/K14) -> 0.7826087
A15: 13 | B15: 46414 | C15: Wednesday | D15: 4 PM - 8 PM | E15: Rath A | F15: Devipatan | G15: Gonda | H15: Eastern UP | I15: Tier 3 | J15: Follow-up | K15: 29 | L15: 4 | M15: 4 | N15: 0 | O15: 25 | P15: =IF(K15=0,0,O15/K15) -> 0.86206897 | Q15: 1 | R15: 0 | S15: 1 | T15: 0 | U15: 0 | V15: 0
A16: 14 | B16: 46414 | C16: Wednesday | D16: 4 PM - 8 PM | E16: Rath B | F16: Moradabad | G16: Amroha | H16: Western UP | I16: Tier 3 | J16: New | K16: 23 | L16: 7 | M16: 4 | N16: 3 | O16: 16 | P16: =IF(K16=0,0,O16/K16) -> 0.69565217
A17: 15 | B17: 46416 | C17: Friday | D17: 4 PM - 8 PM | E17: Rath A | F17: Varanasi | G17: Varanasi | H17: Eastern UP | I17: Tier 3 | J17: Follow-up | K17: 231 | L17: 90 | M17: 57 | N17: 33 | O17: 141 | P17: =IF(K17=0,0,O17/K17) -> 0.61038961 | Q17: 1 | R17: 6 | S17: 0 | T17: 0 | U17: 2 | V17: 0
A18: 16 | B18: 46416 | C18: Friday | D18: 4 PM - 8 PM | E18: Rath B | F18: Meerut | G18: Baghpat | H18: Western UP | I18: Tier 3 | J18: New | K18: 24 | L18: 8 | M18: 7 | N18: 1 | O18: 16 | P18: =IF(K18=0,0,O18/K18) -> 0.66666667
A19: 17 | B19: 46421 | C19: Wednesday | D19: 4 PM - 8 PM | E19: Rath A | F19: Lucknow | G19: Lucknow | H19: Central UP | I19: Tier 2 | J19: Follow-up | K19: 326 | L19: 137 | M19: 90 | N19: 47 | O19: 189 | P19: =IF(K19=0,0,O19/K19) -> 0.5797546 | Q19: 1 | R19: 20 | S19: 0 | T19: 0 | U19: 11 | V19: 2
A20: 18 | B20: 46421 | C20: Wednesday | D20: 4 PM - 8 PM | E20: Rath B | F20: Lucknow | G20: Hardoi | H20: Central UP | I20: Tier 3 | J20: New | K20: 19 | L20: 1 | M20: 1 | N20: 0 | O20: 18 | P20: =IF(K20=0,0,O20/K20) -> 0.94736842
A21: 19 | B21: 46423 | C21: Friday | D21: 4 PM - 8 PM | E21: Rath A | F21: Azamgarh | G21: Azamgarh | H21: Eastern UP | I21: Tier 3 | J21: Follow-up | K21: 36 | L21: 16 | M21: 14 | N21: 2 | O21: 20 | P21: =IF(K21=0,0,O21/K21) -> 0.55555556 | Q21: 1 | R21: 11 | S21: 0 | T21: 0 | U21: 0 | V21: 2
A22: 20 | B22: 46423 | C22: Friday | D22: 4 PM - 8 PM | E22: Rath B | F22: Lucknow | G22: Sitapur | H22: Central UP | I22: Tier 3 | J22: New | K22: 19 | L22: 3 | M22: 2 | N22: 1 | O22: 16 | P22: =IF(K22=0,0,O22/K22) -> 0.84210526
A23: 21 | B23: 46428 | C23: Wednesday | D23: 4 PM - 8 PM | E23: Rath A | F23: Varanasi | G23: Ghazipur | H23: Eastern UP | I23: Tier 3 | J23: New | K23: 20 | L23: 4 | M23: 3 | N23: 1 | O23: 16 | P23: =IF(K23=0,0,O23/K23) -> 0.8
A24: 22 | B24: 46428 | C24: Wednesday | D24: 4 PM - 8 PM | E24: Rath B | F24: Kanpur | G24: Kanpur Dehat | H24: Central UP | I24: Tier 3 | J24: New | K24: 16 | L24: 2 | M24: 2 | N24: 0 | O24: 14 | P24: =IF(K24=0,0,O24/K24) -> 0.875
A25: 23 | B25: 46430 | C25: Friday | D25: 4 PM - 8 PM | E25: Rath A | F25: Azamgarh | G25: Ballia | H25: Eastern UP | I25: Tier 3 | J25: New | K25: 18 | L25: 4 | M25: 4 | N25: 0 | O25: 14 | P25: =IF(K25=0,0,O25/K25) -> 0.77777778
A26: 24 | B26: 46430 | C26: Friday | D26: 4 PM - 8 PM | E26: Rath B | F26: Kanpur | G26: Etawah | H26: Central UP | I26: Tier 3 | J26: New | K26: 16 | L26: 10 | M26: 10 | N26: 0 | O26: 6 | P26: =IF(K26=0,0,O26/K26) -> 0.375
A27: 25 | B27: 46435 | C27: Wednesday | D27: 4 PM - 8 PM | E27: Rath A | F27: Vindhyachal | G27: Sonbhadra | H27: Eastern UP | I27: Tier 3 | J27: New | K27: 20 | L27: 2 | M27: 2 | N27: 0 | O27: 18 | P27: =IF(K27=0,0,O27/K27) -> 0.9
A28: 26 | B28: 46435 | C28: Wednesday | D28: 4 PM - 8 PM | E28: Rath B | F28: Agra | G28: Mainpuri | H28: Western UP | I28: Tier 3 | J28: New | K28: 16 | L28: 3 | M28: 3 | N28: 0 | O28: 13 | P28: =IF(K28=0,0,O28/K28) -> 0.8125
A29: 27 | B29: 46437 | C29: Friday | D29: 4 PM - 8 PM | E29: Rath A | F29: Devipatan | G29: Bahraich | H29: Eastern UP | I29: Tier 3 | J29: Follow-up | K29: 18 | L29: 2 | M29: 2 | N29: 0 | O29: 16 | P29: =IF(K29=0,0,O29/K29) -> 0.88888889 | Q29: 1 | R29: 0 | S29: 0 | T29: 0 | U29: 0 | V29: 0
A30: 28 | B30: 46437 | C30: Friday | D30: 4 PM - 8 PM | E30: Rath B | F30: Agra | G30: Firozabad | H30: Western UP | I30: Tier 3 | J30: New | K30: 18 | L30: 6 | M30: 4 | N30: 2 | O30: 12 | P30: =IF(K30=0,0,O30/K30) -> 0.66666667
A31: 29 | B31: 46442 | C31: Wednesday | D31: 4 PM - 8 PM | E31: Rath A | F31: Basti | G31: Siddharth Nagar | H31: Eastern UP | I31: Tier 3 | J31: New | K31: 16 | L31: 2 | M31: 2 | N31: 0 | O31: 14 | P31: =IF(K31=0,0,O31/K31) -> 0.875
A32: 30 | B32: 46444 | C32: Friday | D32: 4 PM - 8 PM | E32: Rath A | F32: Prayagraj | G32: Fatehpur | H32: Eastern UP | I32: Tier 3 | J32: New | K32: 15 | L32: 0 | M32: 0 | N32: 0 | O32: 15 | P32: =IF(K32=0,0,O32/K32) -> 1
A33: 31 | B33: 46444 | C33: Friday | D33: 4 PM - 8 PM | E33: Rath B | F33: Meerut | G33: Ghaziabad | H33: Western UP | I33: Tier 2 | J33: New | K33: 86 | L33: 141 | M33: 67 | N33: 74 | O33: -55 | P33: =IF(K33=0,0,O33/K33) -> -0.63953488
A34: 32 | B34: 46449 | C34: Wednesday | D34: 4 PM - 8 PM | E34: Rath A | F34: Lucknow | G34: Unnao | H34: Central UP | I34: Tier 3 | J34: New | K34: 21 | L34: 4 | M34: 3 | N34: 1 | O34: 17 | P34: =IF(K34=0,0,O34/K34) -> 0.80952381
A35: 33 | B35: 46449 | C35: Wednesday | D35: 4 PM - 8 PM | E35: Rath B | F35: Meerut | G35: Gautam Buddha Nagar | H35: Western UP | I35: Tier 3 | J35: New | K35: 77 | L35: 146 | M35: 47 | N35: 99 | O35: -69 | P35: =IF(K35=0,0,O35/K35) -> -0.8961039
A37: Source: UP GY Phase 2 plan. Selection: 70% potential on the absolute NABH gap (PM-JAY Universe - NABH Total) + 30% leads (Hot + Application in Progress). Districts with PM-JAY universe under 15 held for Phase 3. Ghaziabad and Gautam Buddha Nagar placed last (negative gap). Rath A/B assigned by order within each date.

Sheet Phase 3 Clusters (Mar 2027)
A1: Yatra # | B1: Event Date | C1: Day | D1: Time | E1: Cluster | F1: Role | G1: Mandal | H1: District | I1: Zone | J1: Tier | K1: Visit Type | L1: PM-JAY Universe | M1: NABH Total | N1: Certified | O1: Accredited | P1: Potential Gap | Q1: % Potential | R1: Yatras Conducted | S1: Attended | T1: Won | U1: Application in Progress | V1: Hot | W1: Warm
A2: TOTAL | H2: 19 districts | L2: =SUM(L3:L21) -> 151 | M2: =SUM(M3:M21) -> 22 | N2: =SUM(N3:N21) -> 21 | O2: =SUM(O3:O21) -> 1 | P2: =SUM(P3:P21) -> 129 | Q2: =IF(L2=0,0,P2/L2) -> 0.85430464 | R2: =SUM(R3:R21) -> 1 | S2: =SUM(S3:S21) -> 20 | T2: =SUM(T3:T21) -> 0 | U2: =SUM(U3:U21) -> 0 | V2: =SUM(V3:V21) -> 0 | W2: =SUM(W3:W21) -> 0
A3: 1 | B3: 46451 | C3: Friday | D3: 4 PM - 8 PM | E3: Hathras Cluster | F3: Host | G3: Aligarh | H3: Hathras | I3: Western UP | J3: Tier 3 | K3: New | L3: 13 | M3: 3 | N3: 2 | O3: 1 | P3: 10 | Q3: =IF(L3=0,0,P3/L3) -> 0.76923077
A4: 1 | B4: 46451 | C4: Friday | D4: 4 PM - 8 PM | E4: Hathras Cluster | F4: Cluster district | G4: Aligarh | H4: Etah | I4: Western UP | J4: Tier 3 | K4: New | L4: 8 | M4: 0 | N4: 0 | O4: 0 | P4: 8 | Q4: =IF(L4=0,0,P4/L4) -> 1
A5: 1 | B5: 46451 | C5: Friday | D5: 4 PM - 8 PM | E5: Hathras Cluster | F5: Cluster district | G5: Aligarh | H5: Kasganj | I5: Western UP | J5: Tier 3 | K5: New | L5: 3 | M5: 0 | N5: 0 | O5: 0 | P5: 3 | Q5: =IF(L5=0,0,P5/L5) -> 1
A6: 2 | B6: 46451 | C6: Friday | D6: 4 PM - 8 PM | E6: Pratapgarh Cluster | F6: Host | G6: Prayagraj | H6: Pratapgarh | I6: Eastern UP | J6: Tier 3 | K6: Follow-up | L6: 9 | M6: 1 | N6: 1 | O6: 0 | P6: 8 | Q6: =IF(L6=0,0,P6/L6) -> 0.88888889 | R6: 1 | S6: 20 | T6: 0 | U6: 0 | V6: 0 | W6: 0
A7: 2 | B7: 46451 | C7: Friday | D7: 4 PM - 8 PM | E7: Pratapgarh Cluster | F7: Cluster district | G7: Lucknow | H7: Rae Bareli | I7: Central UP | J7: Tier 3 | K7: New | L7: 13 | M7: 5 | N7: 5 | O7: 0 | P7: 8 | Q7: =IF(L7=0,0,P7/L7) -> 0.61538462
A8: 2 | B8: 46451 | C8: Friday | D8: 4 PM - 8 PM | E8: Pratapgarh Cluster | F8: Cluster district | G8: Prayagraj | H8: Kaushambi | I8: Eastern UP | J8: Tier 3 | K8: New | L8: 10 | M8: 2 | N8: 2 | O8: 0 | P8: 8 | Q8: =IF(L8=0,0,P8/L8) -> 0.8
A9: 3 | B9: 46458 | C9: Friday | D9: 4 PM - 8 PM | E9: Farrukhabad Cluster | F9: Host | G9: Kanpur | H9: Farrukhabad | I9: Central UP | J9: Tier 3 | K9: New | L9: 14 | M9: 2 | N9: 2 | O9: 0 | P9: 12 | Q9: =IF(L9=0,0,P9/L9) -> 0.85714286
A10: 3 | B10: 46458 | C10: Friday | D10: 4 PM - 8 PM | E10: Farrukhabad Cluster | F10: Cluster district | G10: Kanpur | H10: Kannauj | I10: Central UP | J10: Tier 3 | K10: New | L10: 11 | M10: 2 | N10: 2 | O10: 0 | P10: 9 | Q10: =IF(L10=0,0,P10/L10) -> 0.81818182
A11: 3 | B11: 46458 | C11: Friday | D11: 4 PM - 8 PM | E11: Farrukhabad Cluster | F11: Cluster district | G11: Kanpur | H11: Auraiya | I11: Central UP | J11: Tier 3 | K11: New | L11: 4 | M11: 1 | N11: 1 | O11: 0 | P11: 3 | Q11: =IF(L11=0,0,P11/L11) -> 0.75
A12: 4 | B12: 46458 | C12: Friday | D12: 4 PM - 8 PM | E12: Balrampur Cluster | F12: Host | G12: Devipatan | H12: Balrampur | I12: Eastern UP | J12: Tier 3 | K12: New | L12: 10 | M12: 0 | N12: 0 | O12: 0 | P12: 10 | Q12: =IF(L12=0,0,P12/L12) -> 1
A13: 4 | B13: 46458 | C13: Friday | D13: 4 PM - 8 PM | E13: Balrampur Cluster | F13: Cluster district | G13: Devipatan | H13: Shravasti | I13: Eastern UP | J13: Tier 3 | K13: New | L13: 5 | M13: 0 | N13: 0 | O13: 0 | P13: 5 | Q13: =IF(L13=0,0,P13/L13) -> 1
A14: 5 | B14: 46463 | C14: Wednesday | D14: 4 PM - 8 PM | E14: Budaun Cluster | F14: Host | G14: Bareilly | H14: Budaun | I14: Western UP | J14: Tier 3 | K14: New | L14: 14 | M14: 1 | N14: 1 | O14: 0 | P14: 13 | Q14: =IF(L14=0,0,P14/L14) -> 0.92857143
A15: 5 | B15: 46463 | C15: Wednesday | D15: 4 PM - 8 PM | E15: Budaun Cluster | F15: Cluster district | G15: Moradabad | H15: Sambhal | I15: Western UP | J15: Tier 3 | K15: New | L15: 11 | M15: 1 | N15: 1 | O15: 0 | P15: 10 | Q15: =IF(L15=0,0,P15/L15) -> 0.90909091
A16: 6 | B16: 46465 | C16: Friday | D16: 4 PM - 8 PM | E16: Orai (Jalaun) Cluster | F16: Host | G16: Jhansi | H16: Jalaun | I16: Bundelkhand (South UP) | J16: Tier 3 | K16: New | L16: 11 | M16: 3 | N16: 3 | O16: 0 | P16: 8 | Q16: =IF(L16=0,0,P16/L16) -> 0.72727273
A17: 6 | B17: 46465 | C17: Friday | D17: 4 PM - 8 PM | E17: Orai (Jalaun) Cluster | F17: Cluster district | G17: Jhansi | H17: Lalitpur | I17: Bundelkhand (South UP) | J17: Tier 3 | K17: New | L17: 6 | M17: 0 | N17: 0 | O17: 0 | P17: 6 | Q17: =IF(L17=0,0,P17/L17) -> 1
A18: 7 | B18: 46470 | C18: Wednesday | D18: 4 PM - 8 PM | E18: Banda Cluster | F18: Host | G18: Chitrakoot | H18: Banda | I18: Bundelkhand (South UP) | J18: Tier 3 | K18: New | L18: 3 | M18: 0 | N18: 0 | O18: 0 | P18: 3 | Q18: =IF(L18=0,0,P18/L18) -> 1
... A21: 7 | B21: 46470 | C21: Wednesday | D21: 4 PM - 8 PM | E21: Banda Cluster | F21: Cluster district | G21: Chitrakoot | H21: Hamirpur | I21: Bundelkhand (South UP) | J21: Tier 3 | K21: New | L21: 3 | M21: 1 | N21: 1 | O21: 0 | P21: 2 | Q21: =IF(L21=0,0,P21/L21) -> 0.66666667
A23: Source: UP GY Phase 3 plan. 19 low-universe districts (PM-JAY universe under 15) grouped into 7 cluster yatras, each hosted at the first district named. 31 Mar 2027 held as reserve date / state-level Gunvatta Manthan and certification ceremony.

Sheet Summary
A1: Phase | B1: Window | C1: Yatras | D1: Districts | E1: PM-JAY Universe | F1: NABH Total | G1: Potential Gap | H1: % Potential | I1: Hot Leads | J1: Application in Progress | K1: Warm Leads
A2: TOTAL (all phases) | B2: 09 Oct 2026 - 24 Mar 2027 | C2: =SUM(C3:C5) -> 63 | D2: =SUM(D3:D5) -> 75 | E2: =SUM(E3:E5) -> 3650 | F2: =SUM(F3:F5) -> 1404 | G2: =SUM(G3:G5) -> 2246 | H2: =IF(E2=0,0,G2/E2) -> 0.61534247 | I2: =SUM(I3:I5) -> 71 | J2: =SUM(J3:J5) -> 22 | K2: =SUM(K3:K5) -> 25
A3: Phase 1 | B3: 09 Oct - 27 Nov 2026 | C3: 23 | D3: 23 | E3: ='Phase 1 (Oct-Nov 2026)'!K2 -> 1854 | F3: ='Phase 1 (Oct-Nov 2026)'!L2 -> 588 | G3: ='Phase 1 (Oct-Nov 2026)'!O2 -> 1266 | H3: =IF(E3=0,0,G3/E3) -> 0.6828479 | I3: ='Phase 1 (Oct-Nov 2026)'!U2 -> 46 | J3: ='Phase 1 (Oct-Nov 2026)'!T2 -> 17 | K3: ='Phase 1 (Oct-Nov 2026)'!V2 -> 5
A4: Phase 2 | B4: 06 Jan - 03 Mar 2027 | C4: 33 | D4: 33 | E4: ='Phase 2 (Jan-Mar 2027)'!K2 -> 1645 | F4: ='Phase 2 (Jan-Mar 2027)'!L2 -> 794 | G4: ='Phase 2 (Jan-Mar 2027)'!O2 -> 851 | H4: =IF(E4=0,0,G4/E4) -> 0.51732523 | I4: ='Phase 2 (Jan-Mar 2027)'!U2 -> 25 | J4: ='Phase 2 (Jan-Mar 2027)'!T2 -> 5 | K4: ='Phase 2 (Jan-Mar 2027)'!V2 -> 20
A5: Phase 3 | B5: 05 Mar - 24 Mar 2027 | C5: 7 | D5: 19 | E5: ='Phase 3 Clusters (Mar 2027)'!L2 -> 151 | F5: ='Phase 3 Clusters (Mar 2027)'!M2 -> 22 | G5: ='Phase 3 Clusters (Mar 2027)'!P2 -> 129 | H5: =IF(E5=0,0,G5/E5) -> 0.85430464 | I5: ='Phase 3 Clusters (Mar 2027)'!V2 -> 0 | J5: ='Phase 3 Clusters (Mar 2027)'!U2 -> 0 | K5: ='Phase 3 Clusters (Mar 2027)'!W2 -> 0
A7: Notes
A8: All sessions: NABH Entry Level Certification workshop, 4 PM - 8 PM.
A9: Hospital and lead figures are from 'Updated District List data.xlsx' -> sheet '(VF) Final Sheet' (75 districts).
A10: Potential Gap = PM-JAY Universe - NABH Total. Gautam Buddha Nagar (-69) and Ghaziabad (-55) have a negative gap.
A11: Lead stages: Won = already NABH certified/accredited; Application in Progress; Hot = will take NABH within 6 months; Warm = 6-12 months.
A12: Visit Type: 'Follow-up' = a yatra has already been conducted in that district; 'New' = first visit.
A13: Phase 1 + Phase 2 + Phase 3 = 75 districts, no district counted twice. 63 yatras in total.
A14: State universe: 3,650 PM-JAY empanelled hospitals; NABH 1,404 (955 certified + 449 accredited); potential gap 2,246.
